Workbook

Sheet Database
A1: match_id | B1: phase_name | C1: groupe1 | D1: groupe2 | E1: date | F1: time_utc_plus_2 | G1: datetime_utc_plus_2 | H1: team1 | I1: team2 | J1: cote1 | K1: cote_n | L1: cote2 | M1: status | N1: score1_90 | O1: score2_90 | P1: score1_120 | Q1: score2_120 | R1: score1_tab | S1: score2_tab | T1: final_mpp_score1 | U1: final_mpp_score2 | V1: rarete | W1: tab_flag | X1: score_text | Y1: prono_result | Z1: prono_points_max | AA1: result_irl | AD1: score_max_cumul
A2: =ROW(B2)-1 -> 1 | B2: Tour 1 | C2: A | D2: A | E2: 46184 | F2: 0.875 | G2: =E2+F2 -> 46184.875 | H2: Mexique | I2: Afrique du Sud | J2: 49 | K2: 125 | L2: 148 | M2: Terminé | N2: 2 | O2: 0 | T2: =IF(OR(ISBLANK($N2),ISBLANK($O2)),"",IF(LEFT($B2,4)="Tour",N2,IF($N2<>$O2,N2,P2))) -> 2 | U2: =IF(OR(ISBLANK($N2),ISBLANK($O2)),"",IF(LEFT($B2,4)="Tour",O2,IF($N2<>$O2,O2,Q2))) -> 0 | V2: Exact | W2: {=IF(LEFT($B2,4)="Tour",0,IF(AND($N2=$O2,$P2=$Q2,NOT(ISBLANK(N2:Q2))),1,0))} -> 0 | X2: =IF( LEFT(B2,4)="Tour", N2&"-"&O2, IF(AND(A2>=73,A2<=104), IF(N2<>O2, N2&"-"&O2, IF(P2<>Q2, P2&"-"&Q2, IF(AND(NOT(ISBLANK(N2)),NOT(ISBLANK(O2)),NOT(ISBLANK(P2)),NOT(ISBLANK(Q2)),NOT(ISBLANK(R2)),NOT(ISBLANK(S2))), P2 &"-"&Q2&" (tab "&R2&"-"&S2&")", "" ) ) ) ) ) -> 2-0 | Y2: =IF(X2="-","",IF(T2>U2,H2,IF(T2<U2,I2,"Nul"))) -> Mexique | Z2: =IF(M2="Terminé",IF(T2>U2,J2,IF(T2<U2,L2,K2))+VLOOKUP(V2,Setup_ScoreExactBonus!$A:$D,4,FALSE),"") -> 69 | AA2: =IFERROR( IF(M2="Terminé", IF(AND(NOT(ISBLANK(N2)), NOT(ISBLANK(O2))), IF(LEFT(B2,4)="Tour", Y2, IF(Y2<>"Nul", Y2, IF(R2>S2, H2, I2 ))))), "") -> Mexique | AB2: =IF(M2="Terminé",IF(Z2=MAX($Z$2:$Z$105),2,1),"") -> 1 | AD2: =IF(M2="Terminé",SUMPRODUCT(Z$2:Z2,AB$2:AB2),"") -> 69
A3: =ROW(B3)-1 -> 2 | B3: Tour 1 | C3: A | D3: A | E3: 46185 | F3: 0.16666667 | G3: =E3+F3 -> 46185.167 | H3: Corée du Sud | I3: Tchéquie | J3: 96 | K3: 107 | L3: 91 | M3: Terminé | N3: 2 | O3: 1 | T3: =IF(OR(ISBLANK($N3),ISBLANK($O3)),"",IF(LEFT($B3,4)="Tour",N3,IF($N3<>$O3,N3,P3))) -> 2 | U3: =IF(OR(ISBLANK($N3),ISBLANK($O3)),"",IF(LEFT($B3,4)="Tour",O3,IF($N3<>$O3,O3,Q3))) -> 1 | V3: Exact | W3: {=IF(LEFT($B3,4)="Tour",0,IF(AND($N3=$O3,$P3=$Q3,NOT(ISBLANK(N3:Q3))),1,0))} -> 0 | X3: =IF( LEFT(B3,4)="Tour", N3&"-"&O3, IF(AND(A3>=73,A3<=104), IF(N3<>O3, N3&"-"&O3, IF(P3<>Q3, P3&"-"&Q3, IF(AND(NOT(ISBLANK(N3)),NOT(ISBLANK(O3)),NOT(ISBLANK(P3)),NOT(ISBLANK(Q3)),NOT(ISBLANK(R3)),NOT(ISBLANK(S3))), P3 &"-"&Q3&" (tab "&R3&"-"&S3&")", "" ) ) ) ) ) -> 2-1 | Y3: =IF(X3="-","",IF(T3>U3,H3,IF(T3<U3,I3,"Nul"))) -> Corée du Sud | Z3: =IF(M3="Terminé",IF(T3>U3,J3,IF(T3<U3,L3,K3))+VLOOKUP(V3,Setup_ScoreExactBonus!$A:$D,4,FALSE),"") -> 116 | AA3: =IFERROR( IF(M3="Terminé", IF(AND(NOT(ISBLANK(N3)), NOT(ISBLANK(O3))), IF(LEFT(B3,4)="Tour", Y3, IF(Y3<>"Nul", Y3, IF(R3>S3, H3, I3 ))))), "") -> Corée du Sud | AB3: =IF(M3="Terminé",IF(Z3=MAX($Z$2:$Z$105),2,1),"") -> 1 | AD3: =IF(M3="Terminé",SUMPRODUCT(Z$2:Z3,AB$2:AB3),"") -> 185
A4: =ROW(B4)-1 -> 3 | B4: Tour 1 | C4: B | D4: B | E4: 46185 | F4: 0.875 | G4: =E4+F4 -> 46185.875 | H4: Canada | I4: Bosnie-Herzégovine | J4: 65 | K4: 117 | L4: 125 | M4: Terminé | N4: 1 | O4: 1 | T4: =IF(OR(ISBLANK($N4),ISBLANK($O4)),"",IF(LEFT($B4,4)="Tour",N4,IF($N4<>$O4,N4,P4))) -> 1 | U4: =IF(OR(ISBLANK($N4),ISBLANK($O4)),"",IF(LEFT($B4,4)="Tour",O4,IF($N4<>$O4,O4,Q4))) -> 1 | V4: Exact | W4: {=IF(LEFT($B4,4)="Tour",0,IF(AND($N4=$O4,$P4=$Q4,NOT(ISBLANK(N4:Q4))),1,0))} -> 0 | X4: =IF( LEFT(B4,4)="Tour", N4&"-"&O4, IF(AND(A4>=73,A4<=104), IF(N4<>O4, N4&"-"&O4, IF(P4<>Q4, P4&"-"&Q4, IF(AND(NOT(ISBLANK(N4)),NOT(ISBLANK(O4)),NOT(ISBLANK(P4)),NOT(ISBLANK(Q4)),NOT(ISBLANK(R4)),NOT(ISBLANK(S4))), P4 &"-"&Q4&" (tab "&R4&"-"&S4&")", "" ) ) ) ) ) -> 1-1 | Y4: =IF(X4="-","",IF(T4>U4,H4,IF(T4<U4,I4,"Nul"))) -> Nul | Z4: =IF(M4="Terminé",IF(T4>U4,J4,IF(T4<U4,L4,K4))+VLOOKUP(V4,Setup_ScoreExactBonus!$A:$D,4,FALSE),"") -> 137 | AA4: =IFERROR( IF(M4="Terminé", IF(AND(NOT(ISBLANK(N4)), NOT(ISBLANK(O4))), IF(LEFT(B4,4)="Tour", Y4, IF(Y4<>"Nul", Y4, IF(R4>S4, H4, I4 ))))), "") -> Nul | AB4: =IF(M4="Terminé",IF(Z4=MAX($Z$2:$Z$105),2,1),"") -> 1 | AD4: =IF(M4="Terminé",SUMPRODUCT(Z$2:Z4,AB$2:AB4),"") -> 322
A5: =ROW(B5)-1 -> 4 | B5: Tour 1 | C5: D | D5: D | E5: 46186 | F5: 0.125 | G5: =E5+F5 -> 46186.125 | H5: Etats-Unis | I5: Paraguay | J5: 74 | K5: 113 | L5: 115 | M5: Terminé | N5: 4 | O5: 1 | T5: =IF(OR(ISBLANK($N5),ISBLANK($O5)),"",IF(LEFT($B5,4)="Tour",N5,IF($N5<>$O5,N5,P5))) -> 4 | U5: =IF(OR(ISBLANK($N5),ISBLANK($O5)),"",IF(LEFT($B5,4)="Tour",O5,IF($N5<>$O5,O5,Q5))) -> 1 | V5: Très rare | W5: {=IF(LEFT($B5,4)="Tour",0,IF(AND($N5=$O5,$P5=$Q5,NOT(ISBLANK(N5:Q5))),1,0))} -> 0 | X5: =IF( LEFT(B5,4)="Tour", N5&"-"&O5, IF(AND(A5>=73,A5<=104), IF(N5<>O5, N5&"-"&O5, IF(P5<>Q5, P5&"-"&Q5, IF(AND(NOT(ISBLANK(N5)),NOT(ISBLANK(O5)),NOT(ISBLANK(P5)),NOT(ISBLANK(Q5)),NOT(ISBLANK(R5)),NOT(ISBLANK(S5))), P5 &"-"&Q5&" (tab "&R5&"-"&S5&")", "" ) ) ) ) ) -> 4-1 | Y5: =IF(X5="-","",IF(T5>U5,H5,IF(T5<U5,I5,"Nul"))) -> Etats-Unis | Z5: =IF(M5="Terminé",IF(T5>U5,J5,IF(T5<U5,L5,K5))+VLOOKUP(V5,Setup_ScoreExactBonus!$A:$D,4,FALSE),"") -> 124 | AA5: =IFERROR( IF(M5="Terminé", IF(AND(NOT(ISBLANK(N5)), NOT(ISBLANK(O5))), IF(LEFT(B5,4)="Tour", Y5, IF(Y5<>"Nul", Y5, IF(R5>S5, H5, I5 ))))), "") -> Etats-Unis | AB5: =IF(M5="Terminé",IF(Z5=MAX($Z$2:$Z$105),2,1),"") -> 1 | AD5: =IF(M5="Terminé",SUMPRODUCT(Z$2:Z5,AB$2:AB5),"") -> 446
A6: =ROW(B6)-1 -> 5 | B6: Tour 1 | C6: B | D6: B | E6: 46186 | F6: 0.875 | G6: =E6+F6 -> 46186.875 | H6: Qatar | I6: Suisse | J6: 172 | K6: 141 | L6: 33 | M6: Terminé | N6: 1 | O6: 1 | T6: =IF(OR(ISBLANK($N6),ISBLANK($O6)),"",IF(LEFT($B6,4)="Tour",N6,IF($N6<>$O6,N6,P6))) -> 1 | U6: =IF(OR(ISBLANK($N6),ISBLANK($O6)),"",IF(LEFT($B6,4)="Tour",O6,IF($N6<>$O6,O6,Q6))) -> 1 | V6: Exact | W6: {=IF(LEFT($B6,4)="Tour",0,IF(AND($N6=$O6,$P6=$Q6,NOT(ISBLANK(N6:Q6))),1,0))} -> 0 | X6: =IF( LEFT(B6,4)="Tour", N6&"-"&O6, IF(AND(A6>=73,A6<=104), IF(N6<>O6, N6&"-"&O6, IF(P6<>Q6, P6&"-"&Q6, IF(AND(NOT(ISBLANK(N6)),NOT(ISBLANK(O6)),NOT(ISBLANK(P6)),NOT(ISBLANK(Q6)),NOT(ISBLANK(R6)),NOT(ISBLANK(S6))), P6 &"-"&Q6&" (tab "&R6&"-"&S6&")", "" ) ) ) ) ) -> 1-1 | Y6: =IF(X6="-","",IF(T6>U6,H6,IF(T6<U6,I6,"Nul"))) -> Nul | Z6: =IF(M6="Terminé",IF(T6>U6,J6,IF(T6<U6,L6,K6))+VLOOKUP(V6,Setup_ScoreExactBonus!$A:$D,4,FALSE),"") -> 161 | AA6: =IFERROR( IF(M6="Terminé", IF(AND(NOT(ISBLANK(N6)), NOT(ISBLANK(O6))), IF(LEFT(B6,4)="Tour", Y6, IF(Y6<>"Nul", Y6, IF(R6>S6, H6, I6 ))))), "") -> Nul | AB6: =IF(M6="Terminé",IF(Z6=MAX($Z$2:$Z$105),2,1),"") -> 1 | AD6: =IF(M6="Terminé",SUMPRODUCT(Z$2:Z6,AB$2:AB6),"") -> 607
A7: =ROW(B7)-1 -> 6 | B7: Tour 1 | C7: C | D7: C | E7: 46187 | F7: 0 | G7: =E7+F7 -> 46187 | H7: Brésil | I7: Maroc | J7: 55 | K7: 122 | L7: 140 | M7: Terminé | N7: 1 | O7: 1 | T7: =IF(OR(ISBLANK($N7),ISBLANK($O7)),"",IF(LEFT($B7,4)="Tour",N7,IF($N7<>$O7,N7,P7))) -> 1 | U7: =IF(OR(ISBLANK($N7),ISBLANK($O7)),"",IF(LEFT($B7,4)="Tour",O7,IF($N7<>$O7,O7,Q7))) -> 1 | V7: Exact | W7: {=IF(LEFT($B7,4)="Tour",0,IF(AND($N7=$O7,$P7=$Q7,NOT(ISBLANK(N7:Q7))),1,0))} -> 0 | X7: =IF( LEFT(B7,4)="Tour", N7&"-"&O7, IF(AND(A7>=73,A7<=104), IF(N7<>O7, N7&"-"&O7, IF(P7<>Q7, P7&"-"&Q7, IF(AND(NOT(ISBLANK(N7)),NOT(ISBLANK(O7)),NOT(ISBLANK(P7)),NOT(ISBLANK(Q7)),NOT(ISBLANK(R7)),NOT(ISBLANK(S7))), P7 &"-"&Q7&" (tab "&R7&"-"&S7&")", "" ) ) ) ) ) -> 1-1 | Y7: =IF(X7="-","",IF(T7>U7,H7,IF(T7<U7,I7,"Nul"))) -> Nul | Z7: =IF(M7="Terminé",IF(T7>U7,J7,IF(T7<U7,L7,K7))+VLOOKUP(V7,Setup_ScoreExactBonus!$A:$D,4,FALSE),"") -> 142 | AA7: =IFERROR( IF(M7="Terminé", IF(AND(NOT(ISBLANK(N7)), NOT(ISBLANK(O7))), IF(LEFT(B7,4)="Tour", Y7, IF(Y7<>"Nul", Y7, IF(R7>S7, H7, I7 ))))), "") -> Nul | AB7: =IF(M7="Terminé",IF(Z7=MAX($Z$2:$Z$105),2,1),"") -> 1 | AD7: =IF(M7="Terminé",SUMPRODUCT(Z$2:Z7,AB$2:AB7),"") -> 749
A8: =ROW(B8)-1 -> 7 | B8: Tour 1 | C8: C | D8: C | E8: 46187 | F8: 0.125 | G8: =E8+F8 -> 46187.125 | H8: Haïti | I8: Ecosse | J8: 154 | K8: 131 | L8: 44 | M8: Terminé | N8: 0 | O8: 1 | T8: =IF(OR(ISBLANK($N8),ISBLANK($O8)),"",IF(LEFT($B8,4)="Tour",N8,IF($N8<>$O8,N8,P8))) -> 0 | U8: =IF(OR(ISBLANK($N8),ISBLANK($O8)),"",IF(LEFT($B8,4)="Tour",O8,IF($N8<>$O8,O8,Q8))) -> 1 | V8: Très rare | W8: {=IF(LEFT($B8,4)="Tour",0,IF(AND($N8=$O8,$P8=$Q8,NOT(ISBLANK(N8:Q8))),1,0))} -> 0 | X8: =IF( LEFT(B8,4)="Tour", N8&"-"&O8, IF(AND(A8>=73,A8<=104), IF(N8<>O8, N8&"-"&O8, IF(P8<>Q8, P8&"-"&Q8, IF(AND(NOT(ISBLANK(N8)),NOT(ISBLANK(O8)),NOT(ISBLANK(P8)),NOT(ISBLANK(Q8)),NOT(ISBLANK(R8)),NOT(ISBLANK(S8))), P8 &"-"&Q8&" (tab "&R8&"-"&S8&")", "" ) ) ) ) ) -> 0-1 | Y8: =IF(X8="-","",IF(T8>U8,H8,IF(T8<U8,I8,"Nul"))) -> Ecosse | Z8: =IF(M8="Terminé",IF(T8>U8,J8,IF(T8<U8,L8,K8))+VLOOKUP(V8,Setup_ScoreExactBonus!$A:$D,4,FALSE),"") -> 94 | AA8: =IFERROR( IF(M8="Terminé", IF(AND(NOT(ISBLANK(N8)), NOT(ISBLANK(O8))), IF(LEFT(B8,4)="Tour", Y8, IF(Y8<>"Nul", Y8, IF(R8>S8, H8, I8 ))))), "") -> Ecosse | AB8: =IF(M8="Terminé",IF(Z8=MAX($Z$2:$Z$105),2,1),"") -> 1 | AD8: =IF(M8="Terminé",SUMPRODUCT(Z$2:Z8,AB$2:AB8),"") -> 843
A9: =ROW(B9)-1 -> 8 | B9: Tour 1 | C9: D | D9: D | E9: 46187 | F9: 0.25 | G9: =E9+F9 -> 46187.25 | H9: Australie | I9: Turquie | J9: 126 | K9: 115 | L9: 66 | M9: Terminé | N9: 2 | O9: 0 | T9: =IF(OR(ISBLANK($N9),ISBLANK($O9)),"",IF(LEFT($B9,4)="Tour",N9,IF($N9<>$O9,N9,P9))) -> 2 | U9: =IF(OR(ISBLANK($N9),ISBLANK($O9)),"",IF(LEFT($B9,4)="Tour",O9,IF($N9<>$O9,O9,Q9))) -> 0 | V9: Très rare | W9: {=IF(LEFT($B9,4)="Tour",0,IF(AND($N9=$O9,$P9=$Q9,NOT(ISBLANK(N9:Q9))),1,0))} -> 0 | X9: =IF( LEFT(B9,4)="Tour", N9&"-"&O9, IF(AND(A9>=73,A9<=104), IF(N9<>O9, N9&"-"&O9, IF(P9<>Q9, P9&"-"&Q9, IF(AND(NOT(ISBLANK(N9)),NOT(ISBLANK(O9)),NOT(ISBLANK(P9)),NOT(ISBLANK(Q9)),NOT(ISBLANK(R9)),NOT(ISBLANK(S9))), P9 &"-"&Q9&" (tab "&R9&"-"&S9&")", "" ) ) ) ) ) -> 2-0 | Y9: =IF(X9="-","",IF(T9>U9,H9,IF(T9<U9,I9,"Nul"))) -> Australie | Z9: =IF(M9="Terminé",IF(T9>U9,J9,IF(T9<U9,L9,K9))+VLOOKUP(V9,Setup_ScoreExactBonus!$A:$D,4,FALSE),"") -> 176 | AA9: =IFERROR( IF(M9="Terminé", IF(AND(NOT(ISBLANK(N9)), NOT(ISBLANK(O9))), IF(LEFT(B9,4)="Tour", Y9, IF(Y9<>"Nul", Y9, IF(R9>S9, H9, I9 ))))), "") -> Australie | AB9: =IF(M9="Terminé",IF(Z9=MAX($Z$2:$Z$105),2,1),"") -> 1 | AD9: =IF(M9="Terminé",SUMPRODUCT(Z$2:Z9,AB$2:AB9),"") -> 1019
A10: =ROW(B10)-1 -> 9 | B10: Tour 1 | C10: E | D10: E | E10: 46187 | F10: 0.79166667 | G10: =E10+F10 -> 46187.792 | H10: Allemagne | I10: Curaçao | J10: 15 | K10: 179 | L10: 222 | M10: Terminé | N10: 7 | O10: 1 | T10: =IF(OR(ISBLANK($N10),ISBLANK($O10)),"",IF(LEFT($B10,4)="Tour",N10,IF($N10<>$O10,N10,P10))) -> 7 | U10: =IF(OR(ISBLANK($N10),ISBLANK($O10)),"",IF(LEFT($B10,4)="Tour",O10,IF($N10<>$O10,O10,Q10))) -> 1 | V10: Ultra rare | W10: {=IF(LEFT($B10,4)="Tour",0,IF(AND($N10=$O10,$P10=$Q10,NOT(ISBLANK(N10:Q10))),1,0))} -> 0 | X10: =IF( LEFT(B10,4)="Tour", N10&"-"&O10, IF(AND(A10>=73,A10<=104), IF(N10<>O10, N10&"-"&O10, IF(P10<>Q10, P10&"-"&Q10, IF(AND(NOT(ISBLANK(N10)),NOT(ISBLANK(O10)),NOT(ISBLANK(P10)),NOT(ISBLANK(Q10)),NOT(ISBLANK(R10)),NOT(ISBLANK(S10))), P10 &"-"&Q10&" (tab "&R10&"-"&S10&")", "" ) ) ) ) ) -> 7-1 | Y10: =IF(X10="-","",IF(T10>U10,H10,IF(T10<U10,I10,"Nul"))) -> Allemagne | Z10: =IF(M10="Terminé",IF(T10>U10,J10,IF(T10<U10,L10,K10))+VLOOKUP(V10,Setup_ScoreExactBonus!$A:$D,4,FALSE),"") -> 115 | AA10: =IFERROR( IF(M10="Terminé", IF(AND(NOT(ISBLANK(N10)), NOT(ISBLANK(O10))), IF(LEFT(B10,4)="Tour", Y10, IF(Y10<>"Nul", Y10, IF(R10>S10, H10, I10 ))))), "") -> Allemagne | AB10: =IF(M10="Terminé",IF(Z10=MAX($Z$2:$Z$105),2,1),"") -> 1 | AD10: =IF(M10="Terminé",SUMPRODUCT(Z$2:Z10,AB$2:AB10),"") -> 1134
A11: =ROW(B11)-1 -> 10 | B11: Tour 1 | C11: F | D11: F | E11: 46187 | F11: 0.91666667 | G11: =E11+F11 -> 46187.917 | H11: Pays-Bas | I11: Japon | J11: 74 | K11: 115 | L11: 113 | M11: Terminé | N11: 2 | O11: 2 | T11: =IF(OR(ISBLANK($N11),ISBLANK($O11)),"",IF(LEFT($B11,4)="Tour",N11,IF($N11<>$O11,N11,P11))) -> 2 | U11: =IF(OR(ISBLANK($N11),ISBLANK($O11)),"",IF(LEFT($B11,4)="Tour",O11,IF($N11<>$O11,O11,Q11))) -> 2 | V11: Exact | W11: {=IF(LEFT($B11,4)="Tour",0,IF(AND($N11=$O11,$P11=$Q11,NOT(ISBLANK(N11:Q11))),1,0))} -> 0 | X11: =IF( LEFT(B11,4)="Tour", N11&"-"&O11, IF(AND(A11>=73,A11<=104), IF(N11<>O11, N11&"-"&O11, IF(P11<>Q11, P11&"-"&Q11, IF(AND(NOT(ISBLANK(N11)),NOT(ISBLANK(O11)),NOT(ISBLANK(P11)),NOT(ISBLANK(Q11)),NOT(ISBLANK(R11)),NOT(ISBLANK(S11))), P11 &"-"&Q11&" (tab "&R11&"-"&S11&")", "" ) ) ) ) ) -> 2-2 | Y11: =IF(X11="-","",IF(T11>U11,H11,IF(T11<U11,I11,"Nul"))) -> Nul | Z11: =IF(M11="Terminé",IF(T11>U11,J11,IF(T11<U11,L11,K11))+VLOOKUP(V11,Setup_ScoreExactBonus!$A:$D,4,FALSE),"") -> 135 | AA11: =IFERROR( IF(M11="Terminé", IF(AND(NOT(ISBLANK(N11)), NOT(ISBLANK(O11))), IF(LEFT(B11,4)="Tour", Y11, IF(Y11<>"Nul", Y11, IF(R11>S11, H11, I11 ))))), "") -> Nul | AB11: =IF(M11="Terminé",IF(Z11=MAX($Z$2:$Z$105),2,1),"") -> 1 | AD11: =IF(M11="Terminé",SUMPRODUCT(Z$2:Z11,AB$2:AB11),"") -> 1269
A12: =ROW(B12)-1 -> 11 | B12: Tour 1 | C12: E | D12: E | E12: 46188 | F12: 0.041666667 | G12: =E12+F12 -> 46188.042 | H12: Côte d'Ivoire | I12: Equateur | J12: 108 | K12: 101 | L12: 85 | M12: Terminé | N12: 1 | O12: 0 | T12: =IF(OR(ISBLANK($N12),ISBLANK($O12)),"",IF(LEFT($B12,4)="Tour",N12,IF($N12<>$O12,N12,P12))) -> 1 | U12: =IF(OR(ISBLANK($N12),ISBLANK($O12)),"",IF(LEFT($B12,4)="Tour",O12,IF($N12<>$O12,O12,Q12))) -> 0 | V12: Rare | W12: {=IF(LEFT($B12,4)="Tour",0,IF(AND($N12=$O12,$P12=$Q12,NOT(ISBLANK(N12:Q12))),1,0))} -> 0 | X12: =IF( LEFT(B12,4)="Tour", N12&"-"&O12, IF(AND(A12>=73,A12<=104), IF(N12<>O12, N12&"-"&O12, IF(P12<>Q12, P12&"-"&Q12, IF(AND(NOT(ISBLANK(N12)),NOT(ISBLANK(O12)),NOT(ISBLANK(P12)),NOT(ISBLANK(Q12)),NOT(ISBLANK(R12)),NOT(ISBLANK(S12))), P12 &"-"&Q12&" (tab "&R12&"-"&S12&")", "" ) ) ) ) ) -> 1-0 | Y12: =IF(X12="-","",IF(T12>U12,H12,IF(T12<U12,I12,"Nul"))) -> Côte d'Ivoire | Z12: =IF(M12="Terminé",IF(T12>U12,J12,IF(T12<U12,L12,K12))+VLOOKUP(V12,Setup_ScoreExactBonus!$A:$D,4,FALSE),"") -> 138 | AA12: =IFERROR( IF(M12="Terminé", IF(AND(NOT(ISBLANK(N12)), NOT(ISBLANK(O12))), IF(LEFT(B12,4)="Tour", Y12, IF(Y12<>"Nul", Y12, IF(R12>S12, H12, I12 ))))), "") -> Côte d'Ivoire | AB12: =IF(M12="Terminé",IF(Z12=MAX($Z$2:$Z$105),2,1),"") -> 1 | AD12: =IF(M12="Terminé",SUMPRODUCT(Z$2:Z12,AB$2:AB12),"") -> 1407
A13: =ROW(B13)-1 -> 12 | B13: Tour 1 | C13: F | D13: F | E13: 46188 | F13: 0.16666667 | G13: =E13+F13 -> 46188.167 | H13: Suède | I13: Tunisie | J13: 72 | K13: 110 | L13: 122 | M13: Terminé | N13: 5 | O13: 1 | T13: =IF(OR(ISBLANK($N13),ISBLANK($O13)),"",IF(LEFT($B13,4)="Tour",N13,IF($N13<>$O13,N13,P13))) -> 5 | U13: =IF(OR(ISBLANK($N13),ISBLANK($O13)),"",IF(LEFT($B13,4)="Tour",O13,IF($N13<>$O13,O13,Q13))) -> 1 | V13: Très rare | W13: {=IF(LEFT($B13,4)="Tour",0,IF(AND($N13=$O13,$P13=$Q13,NOT(ISBLANK(N13:Q13))),1,0))} -> 0 | X13: =IF( LEFT(B13,4)="Tour", N13&"-"&O13, IF(AND(A13>=73,A13<=104), IF(N13<>O13, N13&"-"&O13, IF(P13<>Q13, P13&"-"&Q13, IF(AND(NOT(ISBLANK(N13)),NOT(ISBLANK(O13)),NOT(ISBLANK(P13)),NOT(ISBLANK(Q13)),NOT(ISBLANK(R13)),NOT(ISBLANK(S13))), P13 &"-"&Q13&" (tab "&R13&"-"&S13&")", "" ) ) ) ) ) -> 5-1 | Y13: =IF(X13="-","",IF(T13>U13,H13,IF(T13<U13,I13,"Nul"))) -> Suède | Z13: =IF(M13="Terminé",IF(T13>U13,J13,IF(T13<U13,L13,K13))+VLOOKUP(V13,Setup_ScoreExactBonus!$A:$D,4,FALSE),"") -> 122 | AA13: =IFERROR( IF(M13="Terminé", IF(AND(NOT(ISBLANK(N13)), NOT(ISBLANK(O13))), IF(LEFT(B13,4)="Tour", Y13, IF(Y13<>"Nul", Y13, IF(R13>S13, H13, I13 ))))), "") -> Suède | AB13: =IF(M13="Terminé",IF(Z13=MAX($Z$2:$Z$105),2,1),"") -> 1 | AD13: =IF(M13="Terminé",SUMPRODUCT(Z$2:Z13,AB$2:AB13),"") -> 1529
... A75: =ROW(B75)-1 -> 74 | B75: 1/16 Finale | C75: C | D75: F | E75: 46202 | F75: 0.79166667 | G75: =E75+F75 -> 46202.792 | H75: Brésil | I75: Japon | J75: 65 | K75: 121 | L75: 141 | M75: Terminé | N75: 2 | O75: 1 | T75: =IF(OR(ISBLANK($N75),ISBLANK($O75)),"",IF(LEFT($B75,4)="Tour",N75,IF($N75<>$O75,N75,P75))) -> 2 | U75: =IF(OR(ISBLANK($N75),ISBLANK($O75)),"",IF(LEFT($B75,4)="Tour",O75,IF($N75<>$O75,O75,Q75))) -> 1 | V75: Exact | W75: {=IF(LEFT($B75,4)="Tour",0,IF(AND($N75=$O75,$P75=$Q75,NOT(ISBLANK(N75:Q75))),1,0))} -> 0 | X75: =IF( LEFT(B75,4)="Tour", N75&"-"&O75, IF(AND(A75>=73,A75<=104), IF(N75<>O75, N75&"-"&O75, IF(P75<>Q75, P75&"-"&Q75, IF(AND(NOT(ISBLANK(N75)),NOT(ISBLANK(O75)),NOT(ISBLANK(P75)),NOT(ISBLANK(Q75)),NOT(ISBLANK(R75)),NOT(ISBLANK(S75))), P75 &"-"&Q75&" (tab "&R75&"-"&S75&")", "" ) ) ) ) ) -> 2-1 | Y75: =IF(X75="-","",IF(T75>U75,H75,IF(T75<U75,I75,"Nul"))) -> Brésil | Z75: =IF(M75="Terminé",IF(T75>U75,J75,IF(T75<U75,L75,K75))+VLOOKUP(V75,Setup_ScoreExactBonus!$A:$D,4,FALSE),"") -> 85 | AA75: =IFERROR( IF(M75="Terminé", IF(AND(NOT(ISBLANK(N75)), NOT(ISBLANK(O75))), IF(LEFT(B75,4)="Tour", Y75, IF(Y75<>"Nul", Y75, IF(R75>S75, H75, I75 ))))), "") -> Brésil | AB75: =IF(M75="Terminé",IF(Z75=MAX($Z$2:$Z$105),2,1),"") -> 1 | AD75: =IF(M75="Terminé",SUMPRODUCT(Z$2:Z75,AB$2:AB75),"") -> 9048
A76: =ROW(B76)-1 -> 75 | B76: 1/16 Finale | C76: E | D76: ABCDF | E76: 46202 | F76: 0.9375 | G76: =E76+F76 -> 46202.938 | H76: Allemagne | I76: Paraguay | J76: 45 | K76: 140 | L76: 169 | M76: Terminé | N76: 1 | O76: 1 | P76: 1 | Q76: 1 | R76: 3 | S76: 4 | T76: =IF(OR(ISBLANK($N76),ISBLANK($O76)),"",IF(LEFT($B76,4)="Tour",N76,IF($N76<>$O76,N76,P76))) -> 1 | U76: =IF(OR(ISBLANK($N76),ISBLANK($O76)),"",IF(LEFT($B76,4)="Tour",O76,IF($N76<>$O76,O76,Q76))) -> 1 | V76: Exact | W76: {=IF(LEFT($B76,4)="Tour",0,IF(AND($N76=$O76,$P76=$Q76,NOT(ISBLANK(N76:Q76))),1,0))} -> 1 | X76: =IF( LEFT(B76,4)="Tour", N76&"-"&O76, IF(AND(A76>=73,A76<=104), IF(N76<>O76, N76&"-"&O76, IF(P76<>Q76, P76&"-"&Q76, IF(AND(NOT(ISBLANK(N76)),NOT(ISBLANK(O76)),NOT(ISBLANK(P76)),NOT(ISBLANK(Q76)),NOT(ISBLANK(R76)),NOT(ISBLANK(S76))), P76 &"-"&Q76&" (tab "&R76&"-"&S76&")", "" ) ) ) ) ) -> 1-1 (tab 3-4) | Y76: =IF(X76="-","",IF(T76>U76,H76,IF(T76<U76,I76,"Nul"))) -> Nul | Z76: =IF(M76="Terminé",IF(T76>U76,J76,IF(T76<U76,L76,K76))+VLOOKUP(V76,Setup_ScoreExactBonus!$A:$D,4,FALSE),"") -> 160 | AA76: =IFERROR( IF(M76="Terminé", IF(AND(NOT(ISBLANK(N76)), NOT(ISBLANK(O76))), IF(LEFT(B76,4)="Tour", Y76, IF(Y76<>"Nul", Y76, IF(R76>S76, H76, I76 ))))), "") -> Paraguay | AB76: =IF(M76="Terminé",IF(Z76=MAX($Z$2:$Z$105),2,1),"") -> 1 | AD76: =IF(M76="Terminé",SUMPRODUCT(Z$2:Z76,AB$2:AB76),"") -> 9208
A77: =ROW(B77)-1 -> 76 | B77: 1/16 Finale | C77: F | D77: C | E77: 46203 | F77: 0.125 | G77: =E77+F77 -> 46203.125 | H77: Pays-Bas | I77: Maroc | J77: 80 | K77: 114 | L77: 122 | M77: Terminé | N77: 1 | O77: 1 | P77: 1 | Q77: 1 | R77: 2 | S77: 3 | T77: =IF(OR(ISBLANK($N77),ISBLANK($O77)),"",IF(LEFT($B77,4)="Tour",N77,IF($N77<>$O77,N77,P77))) -> 1 | U77: =IF(OR(ISBLANK($N77),ISBLANK($O77)),"",IF(LEFT($B77,4)="Tour",O77,IF($N77<>$O77,O77,Q77))) -> 1 | V77: Exact | W77: {=IF(LEFT($B77,4)="Tour",0,IF(AND($N77=$O77,$P77=$Q77,NOT(ISBLANK(N77:Q77))),1,0))} -> 1 | X77: =IF( LEFT(B77,4)="Tour", N77&"-"&O77, IF(AND(A77>=73,A77<=104), IF(N77<>O77, N77&"-"&O77, IF(P77<>Q77, P77&"-"&Q77, IF(AND(NOT(ISBLANK(N77)),NOT(ISBLANK(O77)),NOT(ISBLANK(P77)),NOT(ISBLANK(Q77)),NOT(ISBLANK(R77)),NOT(ISBLANK(S77))), P77 &"-"&Q77&" (tab "&R77&"-"&S77&")", "" ) ) ) ) ) -> 1-1 (tab 2-3) | Y77: =IF(X77="-","",IF(T77>U77,H77,IF(T77<U77,I77,"Nul"))) -> Nul | Z77: =IF(M77="Terminé",IF(T77>U77,J77,IF(T77<U77,L77,K77))+VLOOKUP(V77,Setup_ScoreExactBonus!$A:$D,4,FALSE),"") -> 134 | AA77: =IFERROR( IF(M77="Terminé", IF(AND(NOT(ISBLANK(N77)), NOT(ISBLANK(O77))), IF(LEFT(B77,4)="Tour", Y77, IF(Y77<>"Nul", Y77, IF(R77>S77, H77, I77 ))))), "") -> Maroc | AB77: =IF(M77="Terminé",IF(Z77=MAX($Z$2:$Z$105),2,1),"") -> 1 | AD77: =IF(M77="Terminé",SUMPRODUCT(Z$2:Z77,AB$2:AB77),"") -> 9342
A78: =ROW(B78)-1 -> 77 | B78: 1/16 Finale | C78: E | D78: I | E78: 46203 | F78: 0.79166667 | G78: =E78+F78 -> 46203.792 | H78: Côte d'Ivoire | I78: Norvège | J78: 123 | K78: 119 | L78: 75 | M78: Terminé | N78: 1 | O78: 2 | T78: =IF(OR(ISBLANK($N78),ISBLANK($O78)),"",IF(LEFT($B78,4)="Tour",N78,IF($N78<>$O78,N78,P78))) -> 1 | U78: =IF(OR(ISBLANK($N78),ISBLANK($O78)),"",IF(LEFT($B78,4)="Tour",O78,IF($N78<>$O78,O78,Q78))) -> 2 | V78: Exact | W78: {=IF(LEFT($B78,4)="Tour",0,IF(AND($N78=$O78,$P78=$Q78,NOT(ISBLANK(N78:Q78))),1,0))} -> 0 | X78: =IF( LEFT(B78,4)="Tour", N78&"-"&O78, IF(AND(A78>=73,A78<=104), IF(N78<>O78, N78&"-"&O78, IF(P78<>Q78, P78&"-"&Q78, IF(AND(NOT(ISBLANK(N78)),NOT(ISBLANK(O78)),NOT(ISBLANK(P78)),NOT(ISBLANK(Q78)),NOT(ISBLANK(R78)),NOT(ISBLANK(S78))), P78 &"-"&Q78&" (tab "&R78&"-"&S78&")", "" ) ) ) ) ) -> 1-2 | Y78: =IF(X78="-","",IF(T78>U78,H78,IF(T78<U78,I78,"Nul"))) -> Norvège | Z78: =IF(M78="Terminé",IF(T78>U78,J78,IF(T78<U78,L78,K78))+VLOOKUP(V78,Setup_ScoreExactBonus!$A:$D,4,FALSE),"") -> 95 | AA78: =IFERROR( IF(M78="Terminé", IF(AND(NOT(ISBLANK(N78)), NOT(ISBLANK(O78))), IF(LEFT(B78,4)="Tour", Y78, IF(Y78<>"Nul", Y78, IF(R78>S78, H78, I78 ))))), "") -> Norvège | AB78: =IF(M78="Terminé",IF(Z78=MAX($Z$2:$Z$105),2,1),"") -> 1 | AD78: =IF(M78="Terminé",SUMPRODUCT(Z$2:Z78,AB$2:AB78),"") -> 9437
A79: =ROW(B79)-1 -> 78 | B79: 1/16 Finale | C79: I | D79: CDFGH | E79: 46203 | F79: 0.95833333 | G79: =E79+F79 -> 46203.958 | H79: France | I79: Suède | J79: 38 | K79: 148 | L79: 182 | M79: Terminé | N79: 3 | O79: 0 | T79: =IF(OR(ISBLANK($N79),ISBLANK($O79)),"",IF(LEFT($B79,4)="Tour",N79,IF($N79<>$O79,N79,P79))) -> 3 | U79: =IF(OR(ISBLANK($N79),ISBLANK($O79)),"",IF(LEFT($B79,4)="Tour",O79,IF($N79<>$O79,O79,Q79))) -> 0 | V79: Rare | W79: {=IF(LEFT($B79,4)="Tour",0,IF(AND($N79=$O79,$P79=$Q79,NOT(ISBLANK(N79:Q79))),1,0))} -> 0 | X79: =IF( LEFT(B79,4)="Tour", N79&"-"&O79, IF(AND(A79>=73,A79<=104), IF(N79<>O79, N79&"-"&O79, IF(P79<>Q79, P79&"-"&Q79, IF(AND(NOT(ISBLANK(N79)),NOT(ISBLANK(O79)),NOT(ISBLANK(P79)),NOT(ISBLANK(Q79)),NOT(ISBLANK(R79)),NOT(ISBLANK(S79))), P79 &"-"&Q79&" (tab "&R79&"-"&S79&")", "" ) ) ) ) ) -> 3-0 | Y79: =IF(X79="-","",IF(T79>U79,H79,IF(T79<U79,I79,"Nul"))) -> France | Z79: =IF(M79="Terminé",IF(T79>U79,J79,IF(T79<U79,L79,K79))+VLOOKUP(V79,Setup_ScoreExactBonus!$A:$D,4,FALSE),"") -> 68 | AA79: =IFERROR( IF(M79="Terminé", IF(AND(NOT(ISBLANK(N79)), NOT(ISBLANK(O79))), IF(LEFT(B79,4)="Tour", Y79, IF(Y79<>"Nul", Y79, IF(R79>S79, H79, I79 ))))), "") -> France | AB79: =IF(M79="Terminé",IF(Z79=MAX($Z$2:$Z$105),2,1),"") -> 1 | AD79: =IF(M79="Terminé",SUMPRODUCT(Z$2:Z79,AB$2:AB79),"") -> 9505
A80: =ROW(B80)-1 -> 79 | B80: 1/16 Finale | C80: A | D80: CEFHI | E80: 46204 | F80: 0.125 | G80: =E80+F80 -> 46204.125 | H80: Mexique | I80: Equateur | J80: 84 | K80: 108 | L80: 122 | M80: Terminé | N80: 2 | O80: 0 | T80: =IF(OR(ISBLANK($N80),ISBLANK($O80)),"",IF(LEFT($B80,4)="Tour",N80,IF($N80<>$O80,N80,P80))) -> 2 | U80: =IF(OR(ISBLANK($N80),ISBLANK($O80)),"",IF(LEFT($B80,4)="Tour",O80,IF($N80<>$O80,O80,Q80))) -> 0 | V80: Rare | W80: {=IF(LEFT($B80,4)="Tour",0,IF(AND($N80=$O80,$P80=$Q80,NOT(ISBLANK(N80:Q80))),1,0))} -> 0 | X80: =IF( LEFT(B80,4)="Tour", N80&"-"&O80, IF(AND(A80>=73,A80<=104), IF(N80<>O80, N80&"-"&O80, IF(P80<>Q80, P80&"-"&Q80, IF(AND(NOT(ISBLANK(N80)),NOT(ISBLANK(O80)),NOT(ISBLANK(P80)),NOT(ISBLANK(Q80)),NOT(ISBLANK(R80)),NOT(ISBLANK(S80))), P80 &"-"&Q80&" (tab "&R80&"-"&S80&")", "" ) ) ) ) ) -> 2-0 | Y80: =IF(X80="-","",IF(T80>U80,H80,IF(T80<U80,I80,"Nul"))) -> Mexique | Z80: =IF(M80="Terminé",IF(T80>U80,J80,IF(T80<U80,L80,K80))+VLOOKUP(V80,Setup_ScoreExactBonus!$A:$D,4,FALSE),"") -> 114 | AA80: =IFERROR( IF(M80="Terminé", IF(AND(NOT(ISBLANK(N80)), NOT(ISBLANK(O80))), IF(LEFT(B80,4)="Tour", Y80, IF(Y80<>"Nul", Y80, IF(R80>S80, H80, I80 ))))), "") -> Mexique | AB80: =IF(M80="Terminé",IF(Z80=MAX($Z$2:$Z$105),2,1),"") -> 1 | AD80: =IF(M80="Terminé",SUMPRODUCT(Z$2:Z80,AB$2:AB80),"") -> 9619
A81: =ROW(B81)-1 -> 80 | B81: 1/16 Finale | C81: L | D81: EHIJK | E81: 46204 | F81: 0.75 | G81: =E81+F81 -> 46204.75 | H81: Angleterre | I81: RD Congo | J81: 39 | K81: 144 | L81: 181 | M81: Terminé | N81: 2 | O81: 1 | T81: =IF(OR(ISBLANK($N81),ISBLANK($O81)),"",IF(LEFT($B81,4)="Tour",N81,IF($N81<>$O81,N81,P81))) -> 2 | U81: =IF(OR(ISBLANK($N81),ISBLANK($O81)),"",IF(LEFT($B81,4)="Tour",O81,IF($N81<>$O81,O81,Q81))) -> 1 | V81: Très rare | W81: {=IF(LEFT($B81,4)="Tour",0,IF(AND($N81=$O81,$P81=$Q81,NOT(ISBLANK(N81:Q81))),1,0))} -> 0 | X81: =IF( LEFT(B81,4)="Tour", N81&"-"&O81, IF(AND(A81>=73,A81<=104), IF(N81<>O81, N81&"-"&O81, IF(P81<>Q81, P81&"-"&Q81, IF(AND(NOT(ISBLANK(N81)),NOT(ISBLANK(O81)),NOT(ISBLANK(P81)),NOT(ISBLANK(Q81)),NOT(ISBLANK(R81)),NOT(ISBLANK(S81))), P81 &"-"&Q81&" (tab "&R81&"-"&S81&")", "" ) ) ) ) ) -> 2-1 | Y81: =IF(X81="-","",IF(T81>U81,H81,IF(T81<U81,I81,"Nul"))) -> Angleterre | Z81: =IF(M81="Terminé",IF(T81>U81,J81,IF(T81<U81,L81,K81))+VLOOKUP(V81,Setup_ScoreExactBonus!$A:$D,4,FALSE),"") -> 89 | AA81: =IFERROR( IF(M81="Terminé", IF(AND(NOT(ISBLANK(N81)), NOT(ISBLANK(O81))), IF(LEFT(B81,4)="Tour", Y81, IF(Y81<>"Nul", Y81, IF(R81>S81, H81, I81 ))))), "") -> Angleterre | AB81: =IF(M81="Terminé",IF(Z81=MAX($Z$2:$Z$105),2,1),"") -> 1 | AD81: =IF(M81="Terminé",SUMPRODUCT(Z$2:Z81,AB$2:AB81),"") -> 9708
A82: =ROW(B82)-1 -> 81 | B82: 1/16 Finale | C82: G | D82: AEHIJ | E82: 46204 | F82: 0.91666667 | G82: =E82+F82 -> 46204.917 | H82: Belgique | I82: Sénégal | J82: 80 | K82: 112 | L82: 123 | M82: Terminé | N82: 0 | O82: 1 | T82: =IF(OR(ISBLANK($N82),ISBLANK($O82)),"",IF(LEFT($B82,4)="Tour",N82,IF($N82<>$O82,N82,P82))) -> 0 | U82: =IF(OR(ISBLANK($N82),ISBLANK($O82)),"",IF(LEFT($B82,4)="Tour",O82,IF($N82<>$O82,O82,Q82))) -> 1 | V82: Très rare | W82: {=IF(LEFT($B82,4)="Tour",0,IF(AND($N82=$O82,$P82=$Q82,NOT(ISBLANK(N82:Q82))),1,0))} -> 0 | X82: =IF( LEFT(B82,4)="Tour", N82&"-"&O82, IF(AND(A82>=73,A82<=104), IF(N82<>O82, N82&"-"&O82, IF(P82<>Q82, P82&"-"&Q82, IF(AND(NOT(ISBLANK(N82)),NOT(ISBLANK(O82)),NOT(ISBLANK(P82)),NOT(ISBLANK(Q82)),NOT(ISBLANK(R82)),NOT(ISBLANK(S82))), P82 &"-"&Q82&" (tab "&R82&"-"&S82&")", "" ) ) ) ) ) -> 0-1 | Y82: =IF(X82="-","",IF(T82>U82,H82,IF(T82<U82,I82,"Nul"))) -> Sénégal | Z82: =IF(M82="Terminé",IF(T82>U82,J82,IF(T82<U82,L82,K82))+VLOOKUP(V82,Setup_ScoreExactBonus!$A:$D,4,FALSE),"") -> 173 | AA82: =IFERROR( IF(M82="Terminé", IF(AND(NOT(ISBLANK(N82)), NOT(ISBLANK(O82))), IF(LEFT(B82,4)="Tour", Y82, IF(Y82<>"Nul", Y82, IF(R82>S82, H82, I82 ))))), "") -> Sénégal | AB82: =IF(M82="Terminé",IF(Z82=MAX($Z$2:$Z$105),2,1),"") -> 1 | AD82: =IF(M82="Terminé",SUMPRODUCT(Z$2:Z82,AB$2:AB82),"") -> 9881
A83: =ROW(B83)-1 -> 82 | B83: 1/16 Finale | C83: D | D83: BEFIJ | E83: 46205 | F83: 0.083333333 | G83: =E83+F83 -> 46205.083 | H83: Etats-Unis | I83: Bosnie-Herzégovine | J83: 52 | K83: 132 | L83: 157 | M83: À venir | T83: =IF(OR(ISBLANK($N83),ISBLANK($O83)),"",IF(LEFT($B83,4)="Tour",N83,IF($N83<>$O83,N83,P83))) | U83: =IF(OR(ISBLANK($N83),ISBLANK($O83)),"",IF(LEFT($B83,4)="Tour",O83,IF($N83<>$O83,O83,Q83))) | V83: Exact | W83: {=IF(LEFT($B83,4)="Tour",0,IF(AND($N83=$O83,$P83=$Q83,NOT(ISBLANK(N83:Q83))),1,0))} -> 0 | X83: =IF( LEFT(B83,4)="Tour", N83&"-"&O83, IF(AND(A83>=73,A83<=104), IF(N83<>O83, N83&"-"&O83, IF(P83<>Q83, P83&"-"&Q83, IF(AND(NOT(ISBLANK(N83)),NOT(ISBLANK(O83)),NOT(ISBLANK(P83)),NOT(ISBLANK(Q83)),NOT(ISBLANK(R83)),NOT(ISBLANK(S83))), P83 &"-"&Q83&" (tab "&R83&"-"&S83&")", "" ) ) ) ) ) | Y83: =IF(X83="-","",IF(T83>U83,H83,IF(T83<U83,I83,"Nul"))) -> Nul | Z83: =IF(M83="Terminé",IF(T83>U83,J83,IF(T83<U83,L83,K83))+VLOOKUP(V83,Setup_ScoreExactBonus!$A:$D,4,FALSE),"") | AA83: =IFERROR( IF(M83="Terminé", IF(AND(NOT(ISBLANK(N83)), NOT(ISBLANK(O83))), IF(LEFT(B83,4)="Tour", Y83, IF(Y83<>"Nul", Y83, IF(R83>S83, H83, I83 ))))), "") -> FALSE | AB83: =IF(M83="Terminé",IF(Z83=MAX($Z$2:$Z$105),2,1),"") | AD83: =IF(M83="Terminé",SUMPRODUCT(Z$2:Z83,AB$2:AB83),"")
A84: =ROW(B84)-1 -> 83 | B84: 1/16 Finale | C84: H | D84: J | E84: 46205 | F84: 0.875 | G84: =E84+F84 -> 46205.875 | H84: Espagne | I84: Autriche | J84: 41 | K84: 140 | L84: 182 | M84: À venir | T84: =IF(OR(ISBLANK($N84),ISBLANK($O84)),"",IF(LEFT($B84,4)="Tour",N84,IF($N84<>$O84,N84,P84))) | U84: =IF(OR(ISBLANK($N84),ISBLANK($O84)),"",IF(LEFT($B84,4)="Tour",O84,IF($N84<>$O84,O84,Q84))) | V84: Exact | W84: {=IF(LEFT($B84,4)="Tour",0,IF(AND($N84=$O84,$P84=$Q84,NOT(ISBLANK(N84:Q84))),1,0))} -> 0 | X84: =IF( LEFT(B84,4)="Tour", N84&"-"&O84, IF(AND(A84>=73,A84<=104), IF(N84<>O84, N84&"-"&O84, IF(P84<>Q84, P84&"-"&Q84, IF(AND(NOT(ISBLANK(N84)),NOT(ISBLANK(O84)),NOT(ISBLANK(P84)),NOT(ISBLANK(Q84)),NOT(ISBLANK(R84)),NOT(ISBLANK(S84))), P84 &"-"&Q84&" (tab "&R84&"-"&S84&")", "" ) ) ) ) ) | Y84: =IF(X84="-","",IF(T84>U84,H84,IF(T84<U84,I84,"Nul"))) -> Nul | Z84: =IF(M84="Terminé",IF(T84>U84,J84,IF(T84<U84,L84,K84))+VLOOKUP(V84,Setup_ScoreExactBonus!$A:$D,4,FALSE),"") | AA84: =IFERROR( IF(M84="Terminé", IF(AND(NOT(ISBLANK(N84)), NOT(ISBLANK(O84))), IF(LEFT(B84,4)="Tour", Y84, IF(Y84<>"Nul", Y84, IF(R84>S84, H84, I84 ))))), "") -> FALSE | AB84: =IF(M84="Terminé",IF(Z84=MAX($Z$2:$Z$105),2,1),"") | AD84: =IF(M84="Terminé",SUMPRODUCT(Z$2:Z84,AB$2:AB84),"")
A85: =ROW(B85)-1 -> 84 | B85: 1/16 Finale | C85: K | D85: L | E85: 46206 | F85: 0.041666667 | G85: =E85+F85 -> 46206.042 | H85: Portugal | I85: Croatie | J85: 73 | K85: 114 | L85: 133 | M85: À venir | T85: =IF(OR(ISBLANK($N85),ISBLANK($O85)),"",IF(LEFT($B85,4)="Tour",N85,IF($N85<>$O85,N85,P85))) | U85: =IF(OR(ISBLANK($N85),ISBLANK($O85)),"",IF(LEFT($B85,4)="Tour",O85,IF($N85<>$O85,O85,Q85))) | V85: Exact | W85: {=IF(LEFT($B85,4)="Tour",0,IF(AND($N85=$O85,$P85=$Q85,NOT(ISBLANK(N85:Q85))),1,0))} -> 0 | X85: =IF( LEFT(B85,4)="Tour", N85&"-"&O85, IF(AND(A85>=73,A85<=104), IF(N85<>O85, N85&"-"&O85, IF(P85<>Q85, P85&"-"&Q85, IF(AND(NOT(ISBLANK(N85)),NOT(ISBLANK(O85)),NOT(ISBLANK(P85)),NOT(ISBLANK(Q85)),NOT(ISBLANK(R85)),NOT(ISBLANK(S85))), P85 &"-"&Q85&" (tab "&R85&"-"&S85&")", "" ) ) ) ) ) | Y85: =IF(X85="-","",IF(T85>U85,H85,IF(T85<U85,I85,"Nul"))) -> Nul | Z85: =IF(M85="Terminé",IF(T85>U85,J85,IF(T85<U85,L85,K85))+VLOOKUP(V85,Setup_ScoreExactBonus!$A:$D,4,FALSE),"") | AA85: =IFERROR( IF(M85="Terminé", IF(AND(NOT(ISBLANK(N85)), NOT(ISBLANK(O85))), IF(LEFT(B85,4)="Tour", Y85, IF(Y85<>"Nul", Y85, IF(R85>S85, H85, I85 ))))), "") -> FALSE | AB85: =IF(M85="Terminé",IF(Z85=MAX($Z$2:$Z$105),2,1),"") | AD85: =IF(M85="Terminé",SUMPRODUCT(Z$2:Z85,AB$2:AB85),"")
A86: =ROW(B86)-1 -> 85 | B86: 1/16 Finale | C86: B | D86: EFGIJ | E86: 46206 | F86: 0.20833333 | G86: =E86+F86 -> 46206.208 | H86: Suisse | I86: Algérie | J86: 61 | K86: 122 | L86: 148 | M86: À venir | T86: =IF(OR(ISBLANK($N86),ISBLANK($O86)),"",IF(LEFT($B86,4)="Tour",N86,IF($N86<>$O86,N86,P86))) | U86: =IF(OR(ISBLANK($N86),ISBLANK($O86)),"",IF(LEFT($B86,4)="Tour",O86,IF($N86<>$O86,O86,Q86))) | V86: Exact | W86: {=IF(LEFT($B86,4)="Tour",0,IF(AND($N86=$O86,$P86=$Q86,NOT(ISBLANK(N86:Q86))),1,0))} -> 0 | X86: =IF( LEFT(B86,4)="Tour", N86&"-"&O86, IF(AND(A86>=73,A86<=104), IF(N86<>O86, N86&"-"&O86, IF(P86<>Q86, P86&"-"&Q86, IF(AND(NOT(ISBLANK(N86)),NOT(ISBLANK(O86)),NOT(ISBLANK(P86)),NOT(ISBLANK(Q86)),NOT(ISBLANK(R86)),NOT(ISBLANK(S86))), P86 &"-"&Q86&" (tab "&R86&"-"&S86&")", "" ) ) ) ) ) | Y86: =IF(X86="-","",IF(T86>U86,H86,IF(T86<U86,I86,"Nul"))) -> Nul | Z86: =IF(M86="Terminé",IF(T86>U86,J86,IF(T86<U86,L86,K86))+VLOOKUP(V86,Setup_ScoreExactBonus!$A:$D,4,FALSE),"") | AA86: =IFERROR( IF(M86="Terminé", IF(AND(NOT(ISBLANK(N86)), NOT(ISBLANK(O86))), IF(LEFT(B86,4)="Tour", Y86, IF(Y86<>"Nul", Y86, IF(R86>S86, H86, I86 ))))), "") -> FALSE | AB86: =IF(M86="Terminé",IF(Z86=MAX($Z$2:$Z$105),2,1),"") | AD86: =IF(M86="Terminé",SUMPRODUCT(Z$2:Z86,AB$2:AB86),"")
A87: =ROW(B87)-1 -> 86 | B87: 1/16 Finale | C87: D | D87: G | E87: 46206 | F87: 0.83333333 | G87: =E87+F87 -> 46206.833 | H87: Australie | I87: Egypte | J87: 113 | K87: 106 | L87: 92 | M87: À venir | T87: =IF(OR(ISBLANK($N87),ISBLANK($O87)),"",IF(LEFT($B87,4)="Tour",N87,IF($N87<>$O87,N87,P87))) | U87: =IF(OR(ISBLANK($N87),ISBLANK($O87)),"",IF(LEFT($B87,4)="Tour",O87,IF($N87<>$O87,O87,Q87))) | V87: Exact | W87: {=IF(LEFT($B87,4)="Tour",0,IF(AND($N87=$O87,$P87=$Q87,NOT(ISBLANK(N87:Q87))),1,0))} -> 0 | X87: =IF( LEFT(B87,4)="Tour", N87&"-"&O87, IF(AND(A87>=73,A87<=104), IF(N87<>O87, N87&"-"&O87, IF(P87<>Q87, P87&"-"&Q87, IF(AND(NOT(ISBLANK(N87)),NOT(ISBLANK(O87)),NOT(ISBLANK(P87)),NOT(ISBLANK(Q87)),NOT(ISBLANK(R87)),NOT(ISBLANK(S87))), P87 &"-"&Q87&" (tab "&R87&"-"&S87&")", "" ) ) ) ) ) | Y87: =IF(X87="-","",IF(T87>U87,H87,IF(T87<U87,I87,"Nul"))) -> Nul | Z87: =IF(M87="Terminé",IF(T87>U87,J87,IF(T87<U87,L87,K87))+VLOOKUP(V87,Setup_ScoreExactBonus!$A:$D,4,FALSE),"") | AA87: =IFERROR( IF(M87="Terminé", IF(AND(NOT(ISBLANK(N87)), NOT(ISBLANK(O87))), IF(LEFT(B87,4)="Tour", Y87, IF(Y87<>"Nul", Y87, IF(R87>S87, H87, I87 ))))), "") -> FALSE | AB87: =IF(M87="Terminé",IF(Z87=MAX($Z$2:$Z$105),2,1),"") | AD87: =IF(M87="Terminé",SUMPRODUCT(Z$2:Z87,AB$2:AB87),"")
A88: =ROW(B88)-1 -> 87 | B88: 1/16 Finale | C88: J | D88: H | E88: 46207 | F88: 0 | G88: =E88+F88 -> 46207 | H88: Argentine | I88: Cap-Vert | J88: 25 | K88: 165 | L88: 213 | M88: À venir | T88: =IF(OR(ISBLANK($N88),ISBLANK($O88)),"",IF(LEFT($B88,4)="Tour",N88,IF($N88<>$O88,N88,P88))) | U88: =IF(OR(ISBLANK($N88),ISBLANK($O88)),"",IF(LEFT($B88,4)="Tour",O88,IF($N88<>$O88,O88,Q88))) | V88: Exact | W88: {=IF(LEFT($B88,4)="Tour",0,IF(AND($N88=$O88,$P88=$Q88,NOT(ISBLANK(N88:Q88))),1,0))} -> 0 | X88: =IF( LEFT(B88,4)="Tour", N88&"-"&O88, IF(AND(A88>=73,A88<=104), IF(N88<>O88, N88&"-"&O88, IF(P88<>Q88, P88&"-"&Q88, IF(AND(NOT(ISBLANK(N88)),NOT(ISBLANK(O88)),NOT(ISBLANK(P88)),NOT(ISBLANK(Q88)),NOT(ISBLANK(R88)),NOT(ISBLANK(S88))), P88 &"-"&Q88&" (tab "&R88&"-"&S88&")", "" ) ) ) ) ) | Y88: =IF(X88="-","",IF(T88>U88,H88,IF(T88<U88,I88,"Nul"))) -> Nul | Z88: =IF(M88="Terminé",IF(T88>U88,J88,IF(T88<U88,L88,K88))+VLOOKUP(V88,Setup_ScoreExactBonus!$A:$D,4,FALSE),"") | AA88: =IFERROR( IF(M88="Terminé", IF(AND(NOT(ISBLANK(N88)), NOT(ISBLANK(O88))), IF(LEFT(B88,4)="Tour", Y88, IF(Y88<>"Nul", Y88, IF(R88>S88, H88, I88 ))))), "") -> FALSE | AB88: =IF(M88="Terminé",IF(Z88=MAX($Z$2:$Z$105),2,1),"") | AD88: =IF(M88="Terminé",SUMPRODUCT(Z$2:Z88,AB$2:AB88),"")
A89: =ROW(B89)-1 -> 88 | B89: 1/16 Finale | C89: K | D89: DEIJL | E89: 46207 | F89: 0.14583333 | G89: =E89+F89 -> 46207.146 | H89: Colombie | I89: Ghana | J89: 66 | K89: 114 | L89: 139 | M89: À venir | T89: =IF(OR(ISBLANK($N89),ISBLANK($O89)),"",IF(LEFT($B89,4)="Tour",N89,IF($N89<>$O89,N89,P89))) | U89: =IF(OR(ISBLANK($N89),ISBLANK($O89)),"",IF(LEFT($B89,4)="Tour",O89,IF($N89<>$O89,O89,Q89))) | V89: Exact | W89: {=IF(LEFT($B89,4)="Tour",0,IF(AND($N89=$O89,$P89=$Q89,NOT(ISBLANK(N89:Q89))),1,0))} -> 0 | X89: =IF( LEFT(B89,4)="Tour", N89&"-"&O89, IF(AND(A89>=73,A89<=104), IF(N89<>O89, N89&"-"&O89, IF(P89<>Q89, P89&"-"&Q89, IF(AND(NOT(ISBLANK(N89)),NOT(ISBLANK(O89)),NOT(ISBLANK(P89)),NOT(ISBLANK(Q89)),NOT(ISBLANK(R89)),NOT(ISBLANK(S89))), P89 &"-"&Q89&" (tab "&R89&"-"&S89&")", "" ) ) ) ) ) | Y89: =IF(X89="-","",IF(T89>U89,H89,IF(T89<U89,I89,"Nul"))) -> Nul | Z89: =IF(M89="Terminé",IF(T89>U89,J89,IF(T89<U89,L89,K89))+VLOOKUP(V89,Setup_ScoreExactBonus!$A:$D,4,FALSE),"") | AA89: =IFERROR( IF(M89="Terminé", IF(AND(NOT(ISBLANK(N89)), NOT(ISBLANK(O89))), IF(LEFT(B89,4)="Tour", Y89, IF(Y89<>"Nul", Y89, IF(R89>S89, H89, I89 ))))), "") -> FALSE | AB89: =IF(M89="Terminé",IF(Z89=MAX($Z$2:$Z$105),2,1),"") | AD89: =IF(M89="Terminé",SUMPRODUCT(Z$2:Z89,AB$2:AB89),"")
A90: =ROW(B90)-1 -> 89 | B90: 1/8 Finale | C90: 73 | D90: 76 | E90: 46207 | F90: 0.79166667 | G90: =E90+F90 -> 46207.792 | H90: =IF(VLOOKUP(C90,$A:$AA,13,FALSE)="Terminé",VLOOKUP(C90,$A:$AA,27,FALSE),"TBD") -> Canada | I90: =IF(VLOOKUP(D90,$A:$AA,13,FALSE)="Terminé",VLOOKUP(D90,$A:$AA,27,FALSE),"TBD") -> Maroc | J90: 137 | K90: 118 | L90: 68 | M90: À venir | T90: =IF(OR(ISBLANK($N90),ISBLANK($O90)),"",IF(LEFT($B90,4)="Tour",N90,IF($N90<>$O90,N90,P90))) | U90: =IF(OR(ISBLANK($N90),ISBLANK($O90)),"",IF(LEFT($B90,4)="Tour",O90,IF($N90<>$O90,O90,Q90))) | V90: Exact | W90: {=IF(LEFT($B90,4)="Tour",0,IF(AND($N90=$O90,$P90=$Q90,NOT(ISBLANK(N90:Q90))),1,0))} -> 0 | X90: =IF( LEFT(B90,4)="Tour", N90&"-"&O90, IF(AND(A90>=73,A90<=104), IF(N90<>O90, N90&"-"&O90, IF(P90<>Q90, P90&"-"&Q90, IF(AND(NOT(ISBLANK(N90)),NOT(ISBLANK(O90)),NOT(ISBLANK(P90)),NOT(ISBLANK(Q90)),NOT(ISBLANK(R90)),NOT(ISBLANK(S90))), P90 &"-"&Q90&" (tab "&R90&"-"&S90&")", "" ) ) ) ) ) | Y90: =IF(X90="-","",IF(T90>U90,H90,IF(T90<U90,I90,"Nul"))) -> Nul | Z90: =IF(M90="Terminé",IF(T90>U90,J90,IF(T90<U90,L90,K90))+VLOOKUP(V90,Setup_ScoreExactBonus!$A:$D,4,FALSE),"") | AA90: =IFERROR( IF(M90="Terminé", IF(AND(NOT(ISBLANK(N90)), NOT(ISBLANK(O90))), IF(LEFT(B90,4)="Tour", Y90, IF(Y90<>"Nul", Y90, IF(R90>S90, H90, I90 ))))), "") -> FALSE | AB90: =IF(M90="Terminé",IF(Z90=MAX($Z$2:$Z$105),2,1),"") | AD90: =IF(M90="Terminé",SUMPRODUCT(Z$2:Z90,AB$2:AB90),"")
A91: =ROW(B91)-1 -> 90 | B91: 1/8 Finale | C91: 75 | D91: 78 | E91: 46207 | F91: 0.95833333 | G91: =E91+F91 -> 46207.958 | H91: =IF(VLOOKUP(C91,$A:$AA,13,FALSE)="Terminé",VLOOKUP(C91,$A:$AA,27,FALSE),"TBD") -> Paraguay | I91: =IF(VLOOKUP(D91,$A:$AA,13,FALSE)="Terminé",VLOOKUP(D91,$A:$AA,27,FALSE),"TBD") -> France | J91: 202 | K91: 161 | L91: 28 | M91: À venir | T91: =IF(OR(ISBLANK($N91),ISBLANK($O91)),"",IF(LEFT($B91,4)="Tour",N91,IF($N91<>$O91,N91,P91))) | U91: =IF(OR(ISBLANK($N91),ISBLANK($O91)),"",IF(LEFT($B91,4)="Tour",O91,IF($N91<>$O91,O91,Q91))) | V91: Exact | W91: {=IF(LEFT($B91,4)="Tour",0,IF(AND($N91=$O91,$P91=$Q91,NOT(ISBLANK(N91:Q91))),1,0))} -> 0 | X91: =IF( LEFT(B91,4)="Tour", N91&"-"&O91, IF(AND(A91>=73,A91<=104), IF(N91<>O91, N91&"-"&O91, IF(P91<>Q91, P91&"-"&Q91, IF(AND(NOT(ISBLANK(N91)),NOT(ISBLANK(O91)),NOT(ISBLANK(P91)),NOT(ISBLANK(Q91)),NOT(ISBLANK(R91)),NOT(ISBLANK(S91))), P91 &"-"&Q91&" (tab "&R91&"-"&S91&")", "" ) ) ) ) ) | Y91: =IF(X91="-","",IF(T91>U91,H91,IF(T91<U91,I91,"Nul"))) -> Nul | Z91: =IF(M91="Terminé",IF(T91>U91,J91,IF(T91<U91,L91,K91))+VLOOKUP(V91,Setup_ScoreExactBonus!$A:$D,4,FALSE),"") | AA91: =IFERROR( IF(M91="Terminé", IF(AND(NOT(ISBLANK(N91)), NOT(ISBLANK(O91))), IF(LEFT(B91,4)="Tour", Y91, IF(Y91<>"Nul", Y91, IF(R91>S91, H91, I91 ))))), "") -> FALSE | AB91: =IF(M91="Terminé",IF(Z91=MAX($Z$2:$Z$105),2,1),"") | AD91: =IF(M91="Terminé",SUMPRODUCT(Z$2:Z91,AB$2:AB91),"")
A92: =ROW(B92)-1 -> 91 | B92: 1/8 Finale | C92: 74 | D92: 77 | E92: 46208 | F92: 0.91666667 | G92: =E92+F92 -> 46208.917 | H92: =IF(VLOOKUP(C92,$A:$AA,13,FALSE)="Terminé",VLOOKUP(C92,$A:$AA,27,FALSE),"TBD") -> Brésil | I92: =IF(VLOOKUP(D92,$A:$AA,13,FALSE)="Terminé",VLOOKUP(D92,$A:$AA,27,FALSE),"TBD") -> Norvège | J92: 72 | K92: 118 | L92: 130 | M92: À venir | T92: =IF(OR(ISBLANK($N92),ISBLANK($O92)),"",IF(LEFT($B92,4)="Tour",N92,IF($N92<>$O92,N92,P92))) | U92: =IF(OR(ISBLANK($N92),ISBLANK($O92)),"",IF(LEFT($B92,4)="Tour",O92,IF($N92<>$O92,O92,Q92))) | V92: Exact | W92: {=IF(LEFT($B92,4)="Tour",0,IF(AND($N92=$O92,$P92=$Q92,NOT(ISBLANK(N92:Q92))),1,0))} -> 0 | X92: =IF( LEFT(B92,4)="Tour", N92&"-"&O92, IF(AND(A92>=73,A92<=104), IF(N92<>O92, N92&"-"&O92, IF(P92<>Q92, P92&"-"&Q92, IF(AND(NOT(ISBLANK(N92)),NOT(ISBLANK(O92)),NOT(ISBLANK(P92)),NOT(ISBLANK(Q92)),NOT(ISBLANK(R92)),NOT(ISBLANK(S92))), P92 &"-"&Q92&" (tab "&R92&"-"&S92&")", "" ) ) ) ) ) | Y92: =IF(X92="-","",IF(T92>U92,H92,IF(T92<U92,I92,"Nul"))) -> Nul | Z92: =IF(M92="Terminé",IF(T92>U92,J92,IF(T92<U92,L92,K92))+VLOOKUP(V92,Setup_ScoreExactBonus!$A:$D,4,FALSE),"") | AA92: =IFERROR( IF(M92="Terminé", IF(AND(NOT(ISBLANK(N92)), NOT(ISBLANK(O92))), IF(LEFT(B92,4)="Tour", Y92, IF(Y92<>"Nul", Y92, IF(R92>S92, H92, I92 ))))), "") -> FALSE | AB92: =IF(M92="Terminé",IF(Z92=MAX($Z$2:$Z$105),2,1),"") | AD92: =IF(M92="Terminé",SUMPRODUCT(Z$2:Z92,AB$2:AB92),"")
A93: =ROW(B93)-1 -> 92 | B93: 1/8 Finale | C93: 79 | D93: 80 | E93: 46209 | F93: 0.083333333 | G93: =E93+F93 -> 46209.083 | H93: =IF(VLOOKUP(C93,$A:$AA,13,FALSE)="Terminé",VLOOKUP(C93,$A:$AA,27,FALSE),"TBD") -> Mexique | I93: =IF(VLOOKUP(D93,$A:$AA,13,FALSE)="Terminé",VLOOKUP(D93,$A:$AA,27,FALSE),"TBD") -> Angleterre | M93: À venir | T93: =IF(OR(ISBLANK($N93),ISBLANK($O93)),"",IF(LEFT($B93,4)="Tour",N93,IF($N93<>$O93,N93,P93))) | U93: =IF(OR(ISBLANK($N93),ISBLANK($O93)),"",IF(LEFT($B93,4)="Tour",O93,IF($N93<>$O93,O93,Q93))) | V93: Exact | W93: {=IF(LEFT($B93,4)="Tour",0,IF(AND($N93=$O93,$P93=$Q93,NOT(ISBLANK(N93:Q93))),1,0))} -> 0 | X93: =IF( LEFT(B93,4)="Tour", N93&"-"&O93, IF(AND(A93>=73,A93<=104), IF(N93<>O93, N93&"-"&O93, IF(P93<>Q93, P93&"-"&Q93, IF(AND(NOT(ISBLANK(N93)),NOT(ISBLANK(O93)),NOT(ISBLANK(P93)),NOT(ISBLANK(Q93)),NOT(ISBLANK(R93)),NOT(ISBLANK(S93))), P93 &"-"&Q93&" (tab "&R93&"-"&S93&")", "" ) ) ) ) ) | Y93: =IF(X93="-","",IF(T93>U93,H93,IF(T93<U93,I93,"Nul"))) -> Nul | Z93: =IF(M93="Terminé",IF(T93>U93,J93,IF(T93<U93,L93,K93))+VLOOKUP(V93,Setup_ScoreExactBonus!$A:$D,4,FALSE),"") | AA93: =IFERROR( IF(M93="Terminé", IF(AND(NOT(ISBLANK(N93)), NOT(ISBLANK(O93))), IF(LEFT(B93,4)="Tour", Y93, IF(Y93<>"Nul", Y93, IF(R93>S93, H93, I93 ))))), "") -> FALSE | AB93: =IF(M93="Terminé",IF(Z93=MAX($Z$2:$Z$105),2,1),"") | AD93: =IF(M93="Terminé",SUMPRODUCT(Z$2:Z93,AB$2:AB93),"")
A94: =ROW(B94)-1 -> 93 | B94: 1/8 Finale | C94: 83 | D94: 84 | E94: 46209 | F94: 0.875 | G94: =E94+F94 -> 46209.875 | H94: =IF(VLOOKUP(C94,$A:$AA,13,FALSE)="Terminé",VLOOKUP(C94,$A:$AA,27,FALSE),"TBD") -> TBD | I94: =IF(VLOOKUP(D94,$A:$AA,13,FALSE)="Terminé",VLOOKUP(D94,$A:$AA,27,FALSE),"TBD") -> TBD | M94: À venir | T94: =IF(OR(ISBLANK($N94),ISBLANK($O94)),"",IF(LEFT($B94,4)="Tour",N94,IF($N94<>$O94,N94,P94))) | U94: =IF(OR(ISBLANK($N94),ISBLANK($O94)),"",IF(LEFT($B94,4)="Tour",O94,IF($N94<>$O94,O94,Q94))) | V94: Exact | W94: {=IF(LEFT($B94,4)="Tour",0,IF(AND($N94=$O94,$P94=$Q94,NOT(ISBLANK(N94:Q94))),1,0))} -> 0 | X94: =IF( LEFT(B94,4)="Tour", N94&"-"&O94, IF(AND(A94>=73,A94<=104), IF(N94<>O94, N94&"-"&O94, IF(P94<>Q94, P94&"-"&Q94, IF(AND(NOT(ISBLANK(N94)),NOT(ISBLANK(O94)),NOT(ISBLANK(P94)),NOT(ISBLANK(Q94)),NOT(ISBLANK(R94)),NOT(ISBLANK(S94))), P94 &"-"&Q94&" (tab "&R94&"-"&S94&")", "" ) ) ) ) ) | Y94: =IF(X94="-","",IF(T94>U94,H94,IF(T94<U94,I94,"Nul"))) -> Nul | Z94: =IF(M94="Terminé",IF(T94>U94,J94,IF(T94<U94,L94,K94))+VLOOKUP(V94,Setup_ScoreExactBonus!$A:$D,4,FALSE),"") | AA94: =IFERROR( IF(M94="Terminé", IF(AND(NOT(ISBLANK(N94)), NOT(ISBLANK(O94))), IF(LEFT(B94,4)="Tour", Y94, IF(Y94<>"Nul", Y94, IF(R94>S94, H94, I94 ))))), "") -> FALSE | AB94: =IF(M94="Terminé",IF(Z94=MAX($Z$2:$Z$105),2,1),"") | AD94: =IF(M94="Terminé",SUMPRODUCT(Z$2:Z94,AB$2:AB94),"")
A95: =ROW(B95)-1 -> 94 | B95: 1/8 Finale | C95: 81 | D95: 82 | E95: 46210 | F95: 0.083333333 | G95: =E95+F95 -> 46210.083 | H95: =IF(VLOOKUP(C95,$A:$AA,13,FALSE)="Terminé",VLOOKUP(C95,$A:$AA,27,FALSE),"TBD") -> Sénégal | I95: =IF(VLOOKUP(D95,$A:$AA,13,FALSE)="Terminé",VLOOKUP(D95,$A:$AA,27,FALSE),"TBD") -> TBD | M95: À venir | T95: =IF(OR(ISBLANK($N95),ISBLANK($O95)),"",IF(LEFT($B95,4)="Tour",N95,IF($N95<>$O95,N95,P95))) | U95: =IF(OR(ISBLANK($N95),ISBLANK($O95)),"",IF(LEFT($B95,4)="Tour",O95,IF($N95<>$O95,O95,Q95))) | V95: Exact | W95: {=IF(LEFT($B95,4)="Tour",0,IF(AND($N95=$O95,$P95=$Q95,NOT(ISBLANK(N95:Q95))),1,0))} -> 0 | X95: =IF( LEFT(B95,4)="Tour", N95&"-"&O95, IF(AND(A95>=73,A95<=104), IF(N95<>O95, N95&"-"&O95, IF(P95<>Q95, P95&"-"&Q95, IF(AND(NOT(ISBLANK(N95)),NOT(ISBLANK(O95)),NOT(ISBLANK(P95)),NOT(ISBLANK(Q95)),NOT(ISBLANK(R95)),NOT(ISBLANK(S95))), P95 &"-"&Q95&" (tab "&R95&"-"&S95&")", "" ) ) ) ) ) | Y95: =IF(X95="-","",IF(T95>U95,H95,IF(T95<U95,I95,"Nul"))) -> Nul | Z95: =IF(M95="Terminé",IF(T95>U95,J95,IF(T95<U95,L95,K95))+VLOOKUP(V95,Setup_ScoreExactBonus!$A:$D,4,FALSE),"") | AA95: =IFERROR( IF(M95="Terminé", IF(AND(NOT(ISBLANK(N95)), NOT(ISBLANK(O95))), IF(LEFT(B95,4)="Tour", Y95, IF(Y95<>"Nul", Y95, IF(R95>S95, H95, I95 ))))), "") -> FALSE | AB95: =IF(M95="Terminé",IF(Z95=MAX($Z$2:$Z$105),2,1),"") | AD95: =IF(M95="Terminé",SUMPRODUCT(Z$2:Z95,AB$2:AB95),"")
A96: =ROW(B96)-1 -> 95 | B96: 1/8 Finale | C96: 85 | D96: 88 | E96: 46210 | F96: 0.75 | G96: =E96+F96 -> 46210.75 | H96: =IF(VLOOKUP(C96,$A:$AA,13,FALSE)="Terminé",VLOOKUP(C96,$A:$AA,27,FALSE),"TBD") -> TBD | I96: =IF(VLOOKUP(D96,$A:$AA,13,FALSE)="Terminé",VLOOKUP(D96,$A:$AA,27,FALSE),"TBD") -> TBD | M96: À venir | T96: =IF(OR(ISBLANK($N96),ISBLANK($O96)),"",IF(LEFT($B96,4)="Tour",N96,IF($N96<>$O96,N96,P96))) | U96: =IF(OR(ISBLANK($N96),ISBLANK($O96)),"",IF(LEFT($B96,4)="Tour",O96,IF($N96<>$O96,O96,Q96))) | V96: Exact | W96: {=IF(LEFT($B96,4)="Tour",0,IF(AND($N96=$O96,$P96=$Q96,NOT(ISBLANK(N96:Q96))),1,0))} -> 0 | X96: =IF( LEFT(B96,4)="Tour", N96&"-"&O96, IF(AND(A96>=73,A96<=104), IF(N96<>O96, N96&"-"&O96, IF(P96<>Q96, P96&"-"&Q96, IF(AND(NOT(ISBLANK(N96)),NOT(ISBLANK(O96)),NOT(ISBLANK(P96)),NOT(ISBLANK(Q96)),NOT(ISBLANK(R96)),NOT(ISBLANK(S96))), P96 &"-"&Q96&" (tab "&R96&"-"&S96&")", "" ) ) ) ) ) | Y96: =IF(X96="-","",IF(T96>U96,H96,IF(T96<U96,I96,"Nul"))) -> Nul | Z96: =IF(M96="Terminé",IF(T96>U96,J96,IF(T96<U96,L96,K96))+VLOOKUP(V96,Setup_ScoreExactBonus!$A:$D,4,FALSE),"") | AA96: =IFERROR( IF(M96="Terminé", IF(AND(NOT(ISBLANK(N96)), NOT(ISBLANK(O96))), IF(LEFT(B96,4)="Tour", Y96, IF(Y96<>"Nul", Y96, IF(R96>S96, H96, I96 ))))), "") -> FALSE | AB96: =IF(M96="Terminé",IF(Z96=MAX($Z$2:$Z$105),2,1),"") | AD96: =IF(M96="Terminé",SUMPRODUCT(Z$2:Z96,AB$2:AB96),"")
A97: =ROW(B97)-1 -> 96 | B97: 1/8 Finale | C97: 86 | D97: 87 | E97: 46210 | F97: 0.91666667 | G97: =E97+F97 -> 46210.917 | H97: =IF(VLOOKUP(C97,$A:$AA,13,FALSE)="Terminé",VLOOKUP(C97,$A:$AA,27,FALSE),"TBD") -> TBD | I97: =IF(VLOOKUP(D97,$A:$AA,13,FALSE)="Terminé",VLOOKUP(D97,$A:$AA,27,FALSE),"TBD") -> TBD | M97: À venir | T97: =IF(OR(ISBLANK($N97),ISBLANK($O97)),"",IF(LEFT($B97,4)="Tour",N97,IF($N97<>$O97,N97,P97))) | U97: =IF(OR(ISBLANK($N97),ISBLANK($O97)),"",IF(LEFT($B97,4)="Tour",O97,IF($N97<>$O97,O97,Q97))) | V97: Exact | W97: {=IF(LEFT($B97,4)="Tour",0,IF(AND($N97=$O97,$P97=$Q97,NOT(ISBLANK(N97:Q97))),1,0))} -> 0 | X97: =IF( LEFT(B97,4)="Tour", N97&"-"&O97, IF(AND(A97>=73,A97<=104), IF(N97<>O97, N97&"-"&O97, IF(P97<>Q97, P97&"-"&Q97, IF(AND(NOT(ISBLANK(N97)),NOT(ISBLANK(O97)),NOT(ISBLANK(P97)),NOT(ISBLANK(Q97)),NOT(ISBLANK(R97)),NOT(ISBLANK(S97))), P97 &"-"&Q97&" (tab "&R97&"-"&S97&")", "" ) ) ) ) ) | Y97: =IF(X97="-","",IF(T97>U97,H97,IF(T97<U97,I97,"Nul"))) -> Nul | Z97: =IF(M97="Terminé",IF(T97>U97,J97,IF(T97<U97,L97,K97))+VLOOKUP(V97,Setup_ScoreExactBonus!$A:$D,4,FALSE),"") | AA97: =IFERROR( IF(M97="Terminé", IF(AND(NOT(ISBLANK(N97)), NOT(ISBLANK(O97))), IF(LEFT(B97,4)="Tour", Y97, IF(Y97<>"Nul", Y97, IF(R97>S97, H97, I97 ))))), "") -> FALSE | AB97: =IF(M97="Terminé",IF(Z97=MAX($Z$2:$Z$105),2,1),"") | AD97: =IF(M97="Terminé",SUMPRODUCT(Z$2:Z97,AB$2:AB97),"")
A98: =ROW(B98)-1 -> 97 | B98: 1/4 Finale | C98: 89 | D98: 90 | E98: 46212 | F98: 0.91666667 | G98: =E98+F98 -> 46212.917 | H98: =IF(VLOOKUP(C98,$A:$AA,13,FALSE)="Terminé",VLOOKUP(C98,$A:$AA,27,FALSE),"TBD") -> TBD | I98: =IF(VLOOKUP(D98,$A:$AA,13,FALSE)="Terminé",VLOOKUP(D98,$A:$AA,27,FALSE),"TBD") -> TBD | M98: À venir | T98: =IF(OR(ISBLANK($N98),ISBLANK($O98)),"",IF(LEFT($B98,4)="Tour",N98,IF($N98<>$O98,N98,P98))) | U98: =IF(OR(ISBLANK($N98),ISBLANK($O98)),"",IF(LEFT($B98,4)="Tour",O98,IF($N98<>$O98,O98,Q98))) | V98: Exact | W98: {=IF(LEFT($B98,4)="Tour",0,IF(AND($N98=$O98,$P98=$Q98,NOT(ISBLANK(N98:Q98))),1,0))} -> 0 | X98: =IF( LEFT(B98,4)="Tour", N98&"-"&O98, IF(AND(A98>=73,A98<=104), IF(N98<>O98, N98&"-"&O98, IF(P98<>Q98, P98&"-"&Q98, IF(AND(NOT(ISBLANK(N98)),NOT(ISBLANK(O98)),NOT(ISBLANK(P98)),NOT(ISBLANK(Q98)),NOT(ISBLANK(R98)),NOT(ISBLANK(S98))), P98 &"-"&Q98&" (tab "&R98&"-"&S98&")", "" ) ) ) ) ) | Y98: =IF(X98="-","",IF(T98>U98,H98,IF(T98<U98,I98,"Nul"))) -> Nul | Z98: =IF(M98="Terminé",IF(T98>U98,J98,IF(T98<U98,L98,K98))+VLOOKUP(V98,Setup_ScoreExactBonus!$A:$D,4,FALSE),"") | AA98: =IFERROR( IF(M98="Terminé", IF(AND(NOT(ISBLANK(N98)), NOT(ISBLANK(O98))), IF(LEFT(B98,4)="Tour", Y98, IF(Y98<>"Nul", Y98, IF(R98>S98, H98, I98 ))))), "") -> FALSE | AB98: =IF(M98="Terminé",IF(Z98=MAX($Z$2:$Z$105),2,1),"") | AD98: =IF(M98="Terminé",SUMPRODUCT(Z$2:Z98,AB$2:AB98),"")
A99: =ROW(B99)-1 -> 98 | B99: 1/4 Finale | C99: 93 | D99: 94 | E99: 46213 | F99: 0.875 | G99: =E99+F99 -> 46213.875 | H99: =IF(VLOOKUP(C99,$A:$AA,13,FALSE)="Terminé",VLOOKUP(C99,$A:$AA,27,FALSE),"TBD") -> TBD | I99: =IF(VLOOKUP(D99,$A:$AA,13,FALSE)="Terminé",VLOOKUP(D99,$A:$AA,27,FALSE),"TBD") -> TBD | M99: À venir | T99: =IF(OR(ISBLANK($N99),ISBLANK($O99)),"",IF(LEFT($B99,4)="Tour",N99,IF($N99<>$O99,N99,P99))) | U99: =IF(OR(ISBLANK($N99),ISBLANK($O99)),"",IF(LEFT($B99,4)="Tour",O99,IF($N99<>$O99,O99,Q99))) | V99: Exact | W99: {=IF(LEFT($B99,4)="Tour",0,IF(AND($N99=$O99,$P99=$Q99,NOT(ISBLANK(N99:Q99))),1,0))} -> 0 | X99: =IF( LEFT(B99,4)="Tour", N99&"-"&O99, IF(AND(A99>=73,A99<=104), IF(N99<>O99, N99&"-"&O99, IF(P99<>Q99, P99&"-"&Q99, IF(AND(NOT(ISBLANK(N99)),NOT(ISBLANK(O99)),NOT(ISBLANK(P99)),NOT(ISBLANK(Q99)),NOT(ISBLANK(R99)),NOT(ISBLANK(S99))), P99 &"-"&Q99&" (tab "&R99&"-"&S99&")", "" ) ) ) ) ) | Y99: =IF(X99="-","",IF(T99>U99,H99,IF(T99<U99,I99,"Nul"))) -> Nul | Z99: =IF(M99="Terminé",IF(T99>U99,J99,IF(T99<U99,L99,K99))+VLOOKUP(V99,Setup_ScoreExactBonus!$A:$D,4,FALSE),"") | AA99: =IFERROR( IF(M99="Terminé", IF(AND(NOT(ISBLANK(N99)), NOT(ISBLANK(O99))), IF(LEFT(B99,4)="Tour", Y99, IF(Y99<>"Nul", Y99, IF(R99>S99, H99, I99 ))))), "") -> FALSE | AB99: =IF(M99="Terminé",IF(Z99=MAX($Z$2:$Z$105),2,1),"") | AD99: =IF(M99="Terminé",SUMPRODUCT(Z$2:Z99,AB$2:AB99),"")
A100: =ROW(B100)-1 -> 99 | B100: 1/4 Finale | C100: 91 | D100: 92 | E100: 46214 | F100: 0.95833333 | G100: =E100+F100 -> 46214.958 | H100: =IF(VLOOKUP(C100,$A:$AA,13,FALSE)="Terminé",VLOOKUP(C100,$A:$AA,27,FALSE),"TBD") -> TBD | I100: =IF(VLOOKUP(D100,$A:$AA,13,FALSE)="Terminé",VLOOKUP(D100,$A:$AA,27,FALSE),"TBD") -> TBD | M100: À venir | T100: =IF(OR(ISBLANK($N100),ISBLANK($O100)),"",IF(LEFT($B100,4)="Tour",N100,IF($N100<>$O100,N100,P100))) | U100: =IF(OR(ISBLANK($N100),ISBLANK($O100)),"",IF(LEFT($B100,4)="Tour",O100,IF($N100<>$O100,O100,Q100))) | V100: Exact | W100: {=IF(LEFT($B100,4)="Tour",0,IF(AND($N100=$O100,$P100=$Q100,NOT(ISBLANK(N100:Q100))),1,0))} -> 0 | X100: =IF( LEFT(B100,4)="Tour", N100&"-"&O100, IF(AND(A100>=73,A100<=104), IF(N100<>O100, N100&"-"&O100, IF(P100<>Q100, P100&"-"&Q100, IF(AND(NOT(ISBLANK(N100)),NOT(ISBLANK(O100)),NOT(ISBLANK(P100)),NOT(ISBLANK(Q100)),NOT(ISBLANK(R100)),NOT(ISBLANK(S100))), P100 &"-"&Q100&" (tab "&R100&"-"&S100&")", "" ) ) ) ) ) | Y100: =IF(X100="-","",IF(T100>U100,H100,IF(T100<U100,I100,"Nul"))) -> Nul | Z100: =IF(M100="Terminé",IF(T100>U100,J100,IF(T100<U100,L100,K100))+VLOOKUP(V100,Setup_ScoreExactBonus!$A:$D,4,FALSE),"") | AA100: =IFERROR( IF(M100="Terminé", IF(AND(NOT(ISBLANK(N100)), NOT(ISBLANK(O100))), IF(LEFT(B100,4)="Tour", Y100, IF(Y100<>"Nul", Y100, IF(R100>S100, H100, I100 ))))), "") -> FALSE | AB100: =IF(M100="Terminé",IF(Z100=MAX($Z$2:$Z$105),2,1),"") | AD100: =IF(M100="Terminé",SUMPRODUCT(Z$2:Z100,AB$2:AB100),"")
A101: =ROW(B101)-1 -> 100 | B101: 1/4 Finale | C101: 95 | D101: 96 | E101: 46215 | F101: 0.125 | G101: =E101+F101 -> 46215.125 | H101: =IF(VLOOKUP(C101,$A:$AA,13,FALSE)="Terminé",VLOOKUP(C101,$A:$AA,27,FALSE),"TBD") -> TBD | I101: =IF(VLOOKUP(D101,$A:$AA,13,FALSE)="Terminé",VLOOKUP(D101,$A:$AA,27,FALSE),"TBD") -> TBD | M101: À venir | T101: =IF(OR(ISBLANK($N101),ISBLANK($O101)),"",IF(LEFT($B101,4)="Tour",N101,IF($N101<>$O101,N101,P101))) | U101: =IF(OR(ISBLANK($N101),ISBLANK($O101)),"",IF(LEFT($B101,4)="Tour",O101,IF($N101<>$O101,O101,Q101))) | V101: Exact | W101: {=IF(LEFT($B101,4)="Tour",0,IF(AND($N101=$O101,$P101=$Q101,NOT(ISBLANK(N101:Q101))),1,0))} -> 0 | X101: =IF( LEFT(B101,4)="Tour", N101&"-"&O101, IF(AND(A101>=73,A101<=104), IF(N101<>O101, N101&"-"&O101, IF(P101<>Q101, P101&"-"&Q101, IF(AND(NOT(ISBLANK(N101)),NOT(ISBLANK(O101)),NOT(ISBLANK(P101)),NOT(ISBLANK(Q101)),NOT(ISBLANK(R101)),NOT(ISBLANK(S101))), P101 &"-"&Q101&" (tab "&R101&"-"&S101&")", "" ) ) ) ) ) | Y101: =IF(X101="-","",IF(T101>U101,H101,IF(T101<U101,I101,"Nul"))) -> Nul | Z101: =IF(M101="Terminé",IF(T101>U101,J101,IF(T101<U101,L101,K101))+VLOOKUP(V101,Setup_ScoreExactBonus!$A:$D,4,FALSE),"") | AA101: =IFERROR( IF(M101="Terminé", IF(AND(NOT(ISBLANK(N101)), NOT(ISBLANK(O101))), IF(LEFT(B101,4)="Tour", Y101, IF(Y101<>"Nul", Y101, IF(R101>S101, H101, I101 ))))), "") -> FALSE | AB101: =IF(M101="Terminé",IF(Z101=MAX($Z$2:$Z$105),2,1),"") | AD101: =IF(M101="Terminé",SUMPRODUCT(Z$2:Z101,AB$2:AB101),"")
...

Sheet Location
A1: Match | B1: date | C1: time | D1: Date/Heure | E1: Phase Id | F1: Phase | G1: Equipe 1 | H1: Equipe 2 | I1: Location | J1: Stadium
A2: =ROW(B2)-1 -> 1 | B2: 46184 | C2: 0.875 | D2: =B2+C2 -> 46184.875 | E2: 1 | F2: Tour 1 | G2: =VLOOKUP($A2,Database!$A:$I,8,FALSE) -> Mexique | H2: =VLOOKUP($A2,Database!$A:$I,9,FALSE) -> Afrique du Sud | I2: Mexique City | J2: Estadio Azteca
A3: =ROW(B3)-1 -> 2 | B3: 46185 | C3: 0.16666667 | D3: =B3+C3 -> 46185.167 | E3: 1 | F3: Tour 1 | G3: =VLOOKUP($A3,Database!$A:$I,8,FALSE) -> Corée du Sud | H3: =VLOOKUP($A3,Database!$A:$I,9,FALSE) -> Tchéquie | I3: Zapopan | J3: Estadio Akron
A4: =ROW(B4)-1 -> 3 | B4: 46185 | C4: 0.875 | D4: =B4+C4 -> 46185.875 | E4: 1 | F4: Tour 1 | G4: =VLOOKUP($A4,Database!$A:$I,8,FALSE) -> Canada | H4: =VLOOKUP($A4,Database!$A:$I,9,FALSE) -> Bosnie-Herzégovine | I4: Toronto | J4: BMO Field
A5: =ROW(B5)-1 -> 4 | B5: 46186 | C5: 0.125 | D5: =B5+C5 -> 46186.125 | E5: 1 | F5: Tour 1 | G5: =VLOOKUP($A5,Database!$A:$I,8,FALSE) -> Etats-Unis | H5: =VLOOKUP($A5,Database!$A:$I,9,FALSE) -> Paraguay | I5: Inglewood, Los Angeles, California | J5: SoFi Stadium
A6: =ROW(B6)-1 -> 5 | B6: 46186 | C6: 0.875 | D6: =B6+C6 -> 46186.875 | E6: 1 | F6: Tour 1 | G6: =VLOOKUP($A6,Database!$A:$I,8,FALSE) -> Qatar | H6: =VLOOKUP($A6,Database!$A:$I,9,FALSE) -> Suisse | I6: Santa Clara, Californie | J6: Levi's Stadium
A7: =ROW(B7)-1 -> 6 | B7: 46187 | C7: 0 | D7: =B7+C7 -> 46187 | E7: 1 | F7: Tour 1 | G7: =VLOOKUP($A7,Database!$A:$I,8,FALSE) -> Brésil | H7: =VLOOKUP($A7,Database!$A:$I,9,FALSE) -> Maroc | I7: East Rutherford, New Jersey/New York | J7: MetLife Stadium
A8: =ROW(B8)-1 -> 7 | B8: 46187 | C8: 0.125 | D8: =B8+C8 -> 46187.125 | E8: 1 | F8: Tour 1 | G8: =VLOOKUP($A8,Database!$A:$I,8,FALSE) -> Haïti | H8: =VLOOKUP($A8,Database!$A:$I,9,FALSE) -> Ecosse | I8: Foxborough | J8: Gillette Stadium
A9: =ROW(B9)-1 -> 8 | B9: 46187 | C9: 0.25 | D9: =B9+C9 -> 46187.25 | E9: 1 | F9: Tour 1 | G9: =VLOOKUP($A9,Database!$A:$I,8,FALSE) -> Australie | H9: =VLOOKUP($A9,Database!$A:$I,9,FALSE) -> Turquie | I9: Vancouver | J9: BC Place
A10: =ROW(B10)-1 -> 9 | B10: 46187 | C10: 0.79166667 | D10: =B10+C10 -> 46187.792 | E10: 1 | F10: Tour 1 | G10: =VLOOKUP($A10,Database!$A:$I,8,FALSE) -> Allemagne | H10: =VLOOKUP($A10,Database!$A:$I,9,FALSE) -> Curaçao | I10: Houston, Texas | J10: NRG Stadium
A11: =ROW(B11)-1 -> 10 | B11: 46187 | C11: 0.91666667 | D11: =B11+C11 -> 46187.917 | E11: 1 | F11: Tour 1 | G11: =VLOOKUP($A11,Database!$A:$I,8,FALSE) -> Pays-Bas | H11: =VLOOKUP($A11,Database!$A:$I,9,FALSE) -> Japon | I11: Arlington, Dallas, Texas | J11: AT&T Stadium
A12: =ROW(B12)-1 -> 11 | B12: 46188 | C12: 0.041666667 | D12: =B12+C12 -> 46188.042 | E12: 1 | F12: Tour 1 | G12: =VLOOKUP($A12,Database!$A:$I,8,FALSE) -> Côte d'Ivoire | H12: =VLOOKUP($A12,Database!$A:$I,9,FALSE) -> Equateur | I12: Philadelphia, Pennsylvania | J12: Lincoln Financial Field
A13: =ROW(B13)-1 -> 12 | B13: 46188 | C13: 0.16666667 | D13: =B13+C13 -> 46188.167 | E13: 1 | F13: Tour 1 | G13: =VLOOKUP($A13,Database!$A:$I,8,FALSE) -> Suède | H13: =VLOOKUP($A13,Database!$A:$I,9,FALSE) -> Tunisie | I13: Monterrey | J13: Estadio BBVA
... A105: =ROW(B105)-1 -> 104 | B105: 46222 | C105: 0.875 | D105: =B105+C105 -> 46222.875 | E105: 9 | F105: Finale | G105: =VLOOKUP($A105,Database!$A:$I,8,FALSE) -> TBD | H105: =VLOOKUP($A105,Database!$A:$I,9,FALSE) -> TBD | I105: East Rutherford, New Jersey/New York | J105: MetLife Stadium

Sheet Phase_de_groupes
B2: =NOW() -> 46204.952
A3: Groupe | B3: Nation | C3: M | D3: V | E3: N | F3: D | G3: BP | H3: BC | I3: GA | J3: Pts | K3: #
A4: A | B4: Mexique | C4: =COUNTIFS(Database!H:H,B4,Database!G:G,"<="&$B$2)+COUNTIFS(Database!I:I,B4,Database!G:G,"<="&$B$2) -> 4 | D4: =COUNTIFS(Database!$H:$H,$B4,Database!$Y:$Y,$B4,Database!$G:$G,"<="&$B$2)+COUNTIFS(Database!$I:$I,$B4,Database!$Y:$Y,$B4,Database!$G:$G,"<="&$B$2) -> 4 | E4: =COUNTIFS(Database!$H:$H,$B4,Database!$Y:$Y,"=Nul",Database!$G:$G,"<="&$B$2)+COUNTIFS(Database!$I:$I,$B4,Database!$Y:$Y,"Nul",Database!$G:$G,"<="&$B$2) -> 0 | F4: =COUNTIFS(Database!$H:$H,$B4,Database!$Y:$Y,"<>"&$B4,Database!$Y:$Y,"<>Nul",Database!$G:$G,"<="&$B$2)+COUNTIFS(Database!$I:$I,$B4,Database!$Y:$Y,"<>"&$B4,Database!$Y:$Y,"<>Nul",Database!$G:$G,"<="&$B$2) -> 0 | G4: =SUMIF(Database!$H:$H,$B4,Database!T:T)+SUMIF(Database!I:I,$B4,Database!U:U) -> 8 | H4: =SUMIF(Database!$H:$H,$B4,Database!U:U)+SUMIF(Database!I:I,$B4,Database!T:T) -> 0 | I4: =G4-H4 -> 8 | J4: =D4*3+E4 -> 12 | K4: =IF(C4>0, _xlfn.RANK.EQ(J4,$J$4:$J$7,0) + COUNTIFS($J$4:$J$7,J4,$I$4:$I$7,">"&I4), "") -> 1
A5: A | B5: Afrique du Sud | C5: =COUNTIFS(Database!H:H,B5,Database!G:G,"<="&$B$2)+COUNTIFS(Database!I:I,B5,Database!G:G,"<="&$B$2) -> 4 | D5: =COUNTIFS(Database!$H:$H,$B5,Database!$Y:$Y,$B5,Database!$G:$G,"<="&$B$2)+COUNTIFS(Database!$I:$I,$B5,Database!$Y:$Y,$B5,Database!$G:$G,"<="&$B$2) -> 1 | E5: =COUNTIFS(Database!$H:$H,$B5,Database!$Y:$Y,"=Nul",Database!$G:$G,"<="&$B$2)+COUNTIFS(Database!$I:$I,$B5,Database!$Y:$Y,"Nul",Database!$G:$G,"<="&$B$2) -> 1 | F5: =COUNTIFS(Database!$H:$H,$B5,Database!$Y:$Y,"<>"&$B5,Database!$Y:$Y,"<>Nul",Database!$G:$G,"<="&$B$2)+COUNTIFS(Database!$I:$I,$B5,Database!$Y:$Y,"<>"&$B5,Database!$Y:$Y,"<>Nul",Database!$G:$G,"<="&$B$2) -> 2 | G5: =SUMIF(Database!$H:$H,$B5,Database!T:T)+SUMIF(Database!I:I,$B5,Database!U:U) -> 2 | H5: =SUMIF(Database!$H:$H,$B5,Database!U:U)+SUMIF(Database!I:I,$B5,Database!T:T) -> 4 | I5: =G5-H5 -> -2 | J5: =D5*3+E5 -> 4 | K5: =IF(C5>0, _xlfn.RANK.EQ(J5,$J$4:$J$7,0) + COUNTIFS($J$4:$J$7,J5,$I$4:$I$7,">"&I5), "") -> 2
A6: A | B6: Corée du Sud | C6: =COUNTIFS(Database!H:H,B6,Database!G:G,"<="&$B$2)+COUNTIFS(Database!I:I,B6,Database!G:G,"<="&$B$2) -> 3 | D6: =COUNTIFS(Database!$H:$H,$B6,Database!$Y:$Y,$B6,Database!$G:$G,"<="&$B$2)+COUNTIFS(Database!$I:$I,$B6,Database!$Y:$Y,$B6,Database!$G:$G,"<="&$B$2) -> 1 | E6: =COUNTIFS(Database!$H:$H,$B6,Database!$Y:$Y,"=Nul",Database!$G:$G,"<="&$B$2)+COUNTIFS(Database!$I:$I,$B6,Database!$Y:$Y,"Nul",Database!$G:$G,"<="&$B$2) -> 0 | F6: =COUNTIFS(Database!$H:$H,$B6,Database!$Y:$Y,"<>"&$B6,Database!$Y:$Y,"<>Nul",Database!$G:$G,"<="&$B$2)+COUNTIFS(Database!$I:$I,$B6,Database!$Y:$Y,"<>"&$B6,Database!$Y:$Y,"<>Nul",Database!$G:$G,"<="&$B$2) -> 2 | G6: =SUMIF(Database!$H:$H,$B6,Database!T:T)+SUMIF(Database!I:I,$B6,Database!U:U) -> 2 | H6: =SUMIF(Database!$H:$H,$B6,Database!U:U)+SUMIF(Database!I:I,$B6,Database!T:T) -> 3 | I6: =G6-H6 -> -1 | J6: =D6*3+E6 -> 3 | K6: =IF(C6>0, _xlfn.RANK.EQ(J6,$J$4:$J$7,0) + COUNTIFS($J$4:$J$7,J6,$I$4:$I$7,">"&I6), "") -> 3
A7: A | B7: Tchéquie | C7: =COUNTIFS(Database!H:H,B7,Database!G:G,"<="&$B$2)+COUNTIFS(Database!I:I,B7,Database!G:G,"<="&$B$2) -> 3 | D7: =COUNTIFS(Database!$H:$H,$B7,Database!$Y:$Y,$B7,Database!$G:$G,"<="&$B$2)+COUNTIFS(Database!$I:$I,$B7,Database!$Y:$Y,$B7,Database!$G:$G,"<="&$B$2) -> 0 | E7: =COUNTIFS(Database!$H:$H,$B7,Database!$Y:$Y,"=Nul",Database!$G:$G,"<="&$B$2)+COUNTIFS(Database!$I:$I,$B7,Database!$Y:$Y,"Nul",Database!$G:$G,"<="&$B$2) -> 1 | F7: =COUNTIFS(Database!$H:$H,$B7,Database!$Y:$Y,"<>"&$B7,Database!$Y:$Y,"<>Nul",Database!$G:$G,"<="&$B$2)+COUNTIFS(Database!$I:$I,$B7,Database!$Y:$Y,"<>"&$B7,Database!$Y:$Y,"<>Nul",Database!$G:$G,"<="&$B$2) -> 2 | G7: =SUMIF(Database!$H:$H,$B7,Database!T:T)+SUMIF(Database!I:I,$B7,Database!U:U) -> 2 | H7: =SUMIF(Database!$H:$H,$B7,Database!U:U)+SUMIF(Database!I:I,$B7,Database!T:T) -> 6 | I7: =G7-H7 -> -4 | J7: =D7*3+E7 -> 1 | K7: =IF(C7>0, _xlfn.RANK.EQ(J7,$J$4:$J$7,0) + COUNTIFS($J$4:$J$7,J7,$I$4:$I$7,">"&I7), "") -> 4
